Workbook
Name QF_M_ClientID: Lists!$M$1
Name QF_M_ClientName: Lists!$M$2
Name QF_M_Version: Lists!$M$3
Name QF_M_ExportedAt: Lists!$M$4
Name QF_M_ExportedBy: Lists!$M$5
Name QF_M_TemplateVersion: Lists!$M$6
Name QF_Client: Inputs!$C$8
Name QF_First: Inputs!$C$9
Name QF_Adviser: Inputs!$C$10
Name QF_Date: Inputs!$C$11
Name QF_AsAt: Inputs!$C$12
Name QF_Marital: Inputs!$C$13
Name QF_Residue: Inputs!$C$14
Name QF_Wishes: Inputs!$C$15
Name QF_TI: Inputs!$C$16
Name QF_TINote: Inputs!$C$17
Name QF_K_assets: Inputs!$B$20:$I$20
Name QF_T_assets: Inputs!$B$22:$I$39
Name QF_K_debts: Inputs!$B$43:$I$43
Name QF_T_debts: Inputs!$B$45:$I$54
Name QF_K_cover: Inputs!$B$57:$I$57
Name QF_T_cover: Inputs!$B$59:$I$70
Name QF_K_funds: Inputs!$B$74:$I$74
Name QF_T_funds: Inputs!$B$76:$I$83
Name QF_K_deps: Inputs!$B$87:$I$87
Name QF_T_deps: Inputs!$B$89:$I$94
Name QF_L_whom: Inputs!$Z$88:$Z$94
Name QF_KidsShare: Inputs!$C$95
Name QF_QuoteNo: Inputs!$C$99
Name QF_CLFee: Inputs!$C$100
Name QF_CLConv: Inputs!$C$101
Name QF_CLPays: Inputs!$C$102
Name QF_CLLimit: Inputs!$C$103
Name QF_CLPrem: Inputs!$C$104
Name QF_A_ExecFee: Inputs!$C$108
Name QF_A_VAT: Inputs!$C$109
Name QF_A_Master: Inputs!$C$110
Name QF_A_Funeral: Inputs!$C$111
Name QF_A_Sundries: Inputs!$C$112
Name QF_A_PropCost: Inputs!$C$113
Name QF_A_Agent: Inputs!$C$114
Name QF_A_Abatement: Inputs!$C$115
Name QF_A_DutyRate: Inputs!$C$116
Name QF_A_DutyBand: Inputs!$C$117
Name QF_A_DutyHigh: Inputs!$C$118
Name QF_A_CGTExcl: Inputs!$C$119
Name QF_A_Inclusion: Inputs!$C$120
Name QF_A_PRExcl: Inputs!$C$121
Name QF_A_Gross: Inputs!$C$122
Name QF_A_TrustFee: Inputs!$H$108
Name QF_A_Threshold: Inputs!$H$109
Name QF_A_Interest: Inputs!$H$110
Name QF_A_Dividends: Inputs!$H$111
Name QF_A_Growth: Inputs!$H$112
Name QF_A_DivTax: Inputs!$H$113
Name QF_A_CPI: Inputs!$H$114
Name QF_A_LAMin: Inputs!$H$115
Name QF_A_LAMax: Inputs!$H$116
Name QF_A_Rebate1: Inputs!$H$117
Name QF_A_Rebate2: Inputs!$H$118

Sheet Lists
A1: kind | B1: passes | C1: paidTo | D1: yesno | E1: residue | F1: rel | G1: kidsShare | H1: potShare | I1: closeWith | J1: marital | L1: ClientID
A2: Property | B2: Estate (residue) | C2: Estate | D2: Yes | E2: Heirs (people) | F2: Spouse | G2: In equal shares | H2: Equal shares | I2: Nothing | J2: Single | L2: ClientName
A3: Cash and deposits | B3: Spouse | C3: Spouse | D3: No | E3: Spouse | F3: Child | G3: As one family pot | H3: One family pot | I3: New life cover | J3: Engaged | L3: Version | M3: 2.0
A4: Shares and unit trusts | B4: Named heir | C4: Named person | F4: Other | G4: Not to the dependants | I4: Part of a nomination | J4: Married - ANC with accrual | L4: ExportedAt
A5: Other investment | I5: All of a nomination | J5: Married - ANC without accrual | L5: ExportedBy
A6: Tax-free investment | J6: Married in COP | L6: TemplateVersion | M6: 2.0
A7: Loan account | J7: Life partner
A8: Vehicle or contents | J8: Divorced
A9: Business interest | J9: Widowed
J10: Married
J11: Civil Union
J12: Co-Habitation

Sheet Inputs
B1: Duwalcoe Financial Consultants CC
B2: FSP 9978 | clinton@duwalcoe.co.za | 083 608 5617
B4: Inputs: check the yellow cells
B5: The CRM fills this sheet from the client's record. Yellow cells are yours to change; everything else works itself out.
B7: 1. The client
B8: Client
B9: First name, for the wording
B10: Prepared by
B11: Date of this FNA
B12: Values as at
B13: Marital status
B14: Who inherits the residue
... B19: 2. What they own (in the estate)
B20: name | C20: kind | D20: value | E20: base | F20: home | G20: passes | H20: sold | I20: notes
B21: Asset | C21: Kind | D21: Value (R) | E21: Base cost (R) | F21: Main home? | G21: Passes to | H21: Executor sells or cashes it? | I21: Notes | J21: Gain for capital gains tax
J22: =IF(L22=1,M22-N22,"") | L22: =IF(AND(OR(C22="Property",C22="Shares and unit trusts",C22="Other investment",C22="Business interest"),NOT(OR(G22="Spouse",AND(G22="Estate (residue)",'Inputs'!$C$14="Spouse")))),1,0) | M22: =IF(L22=1,N(D22)-N(E22),0) | N22: =IF(AND(L22=1,F22="Yes",M22>0),MIN(M22,'Inputs'!$C$121),0) | O22: =IF(OR(C22="Cash and deposits",H22="Yes"),N(D22),0) | P22: =IF(C22="Property",ROUND('Inputs'!$C$113/100*N(D22),2),0) | Q22: =IF(AND(C22="Property",H22="Yes"),ROUND('Inputs'!$C$114/100*(1+'Inputs'!$C$109/100)*N(D22),2),0) | R22: =IF(G22="Spouse",N(D22),0) | S22: =IF(G22="Named heir",N(D22),0) | T22: =IF(AND(L22=1,N(D22)>0,E22=""),1,0) | U22: =ROUND('Workings'!$C$37*S22,2) | V22: =ROUND('Workings'!$D$37*S22,2) | W22: =IF(AND(B22="",N(D22)=0),0,IF(OR(C22="",G22=""),1,0)) | X22: =IF(S22>0,COUNTIF(S$22:S22,">0"),0) | Y22: =IF(AND(G22="Estate (residue)",H22<>"Yes",OR(C22="Shares and unit trusts",C22="Other investment",C22="Tax-free investment")),N(D22),0)
J23: =IF(L23=1,M23-N23,"") | L23: =IF(AND(OR(C23="Property",C23="Shares and unit trusts",C23="Other investment",C23="Business interest"),NOT(OR(G23="Spouse",AND(G23="Estate (residue)",'Inputs'!$C$14="Spouse")))),1,0) | M23: =IF(L23=1,N(D23)-N(E23),0) | N23: =IF(AND(L23=1,F23="Yes",M23>0),MIN(M23,'Inputs'!$C$121),0) | O23: =IF(OR(C23="Cash and deposits",H23="Yes"),N(D23),0) | P23: =IF(C23="Property",ROUND('Inputs'!$C$113/100*N(D23),2),0) | Q23: =IF(AND(C23="Property",H23="Yes"),ROUND('Inputs'!$C$114/100*(1+'Inputs'!$C$109/100)*N(D23),2),0) | R23: =IF(G23="Spouse",N(D23),0) | S23: =IF(G23="Named heir",N(D23),0) | T23: =IF(AND(L23=1,N(D23)>0,E23=""),1,0) | U23: =ROUND('Workings'!$C$37*S23,2) | V23: =ROUND('Workings'!$D$37*S23,2) | W23: =IF(AND(B23="",N(D23)=0),0,IF(OR(C23="",G23=""),1,0)) | X23: =IF(S23>0,COUNTIF(S$22:S23,">0"),0) | Y23: =IF(AND(G23="Estate (residue)",H23<>"Yes",OR(C23="Shares and unit trusts",C23="Other investment",C23="Tax-free investment")),N(D23),0)
J24: =IF(L24=1,M24-N24,"") | L24: =IF(AND(OR(C24="Property",C24="Shares and unit trusts",C24="Other investment",C24="Business interest"),NOT(OR(G24="Spouse",AND(G24="Estate (residue)",'Inputs'!$C$14="Spouse")))),1,0) | M24: =IF(L24=1,N(D24)-N(E24),0) | N24: =IF(AND(L24=1,F24="Yes",M24>0),MIN(M24,'Inputs'!$C$121),0) | O24: =IF(OR(C24="Cash and deposits",H24="Yes"),N(D24),0) | P24: =IF(C24="Property",ROUND('Inputs'!$C$113/100*N(D24),2),0) | Q24: =IF(AND(C24="Property",H24="Yes"),ROUND('Inputs'!$C$114/100*(1+'Inputs'!$C$109/100)*N(D24),2),0) | R24: =IF(G24="Spouse",N(D24),0) | S24: =IF(G24="Named heir",N(D24),0) | T24: =IF(AND(L24=1,N(D24)>0,E24=""),1,0) | U24: =ROUND('Workings'!$C$37*S24,2) | V24: =ROUND('Workings'!$D$37*S24,2) | W24: =IF(AND(B24="",N(D24)=0),0,IF(OR(C24="",G24=""),1,0)) | X24: =IF(S24>0,COUNTIF(S$22:S24,">0"),0) | Y24: =IF(AND(G24="Estate (residue)",H24<>"Yes",OR(C24="Shares and unit trusts",C24="Other investment",C24="Tax-free investment")),N(D24),0)
J25: =IF(L25=1,M25-N25,"") | L25: =IF(AND(OR(C25="Property",C25="Shares and unit trusts",C25="Other investment",C25="Business interest"),NOT(OR(G25="Spouse",AND(G25="Estate (residue)",'Inputs'!$C$14="Spouse")))),1,0) | M25: =IF(L25=1,N(D25)-N(E25),0) | N25: =IF(AND(L25=1,F25="Yes",M25>0),MIN(M25,'Inputs'!$C$121),0) | O25: =IF(OR(C25="Cash and deposits",H25="Yes"),N(D25),0) | P25: =IF(C25="Property",ROUND('Inputs'!$C$113/100*N(D25),2),0) | Q25: =IF(AND(C25="Property",H25="Yes"),ROUND('Inputs'!$C$114/100*(1+'Inputs'!$C$109/100)*N(D25),2),0) | R25: =IF(G25="Spouse",N(D25),0) | S25: =IF(G25="Named heir",N(D25),0) | T25: =IF(AND(L25=1,N(D25)>0,E25=""),1,0) | U25: =ROUND('Workings'!$C$37*S25,2) | V25: =ROUND('Workings'!$D$37*S25,2) | W25: =IF(AND(B25="",N(D25)=0),0,IF(OR(C25="",G25=""),1,0)) | X25: =IF(S25>0,COUNTIF(S$22:S25,">0"),0) | Y25: =IF(AND(G25="Estate (residue)",H25<>"Yes",OR(C25="Shares and unit trusts",C25="Other investment",C25="Tax-free investment")),N(D25),0)
J26: =IF(L26=1,M26-N26,"") | L26: =IF(AND(OR(C26="Property",C26="Shares and unit trusts",C26="Other investment",C26="Business interest"),NOT(OR(G26="Spouse",AND(G26="Estate (residue)",'Inputs'!$C$14="Spouse")))),1,0) | M26: =IF(L26=1,N(D26)-N(E26),0) | N26: =IF(AND(L26=1,F26="Yes",M26>0),MIN(M26,'Inputs'!$C$121),0) | O26: =IF(OR(C26="Cash and deposits",H26="Yes"),N(D26),0) | P26: =IF(C26="Property",ROUND('Inputs'!$C$113/100*N(D26),2),0) | Q26: =IF(AND(C26="Property",H26="Yes"),ROUND('Inputs'!$C$114/100*(1+'Inputs'!$C$109/100)*N(D26),2),0) | R26: =IF(G26="Spouse",N(D26),0) | S26: =IF(G26="Named heir",N(D26),0) | T26: =IF(AND(L26=1,N(D26)>0,E26=""),1,0) | U26: =ROUND('Workings'!$C$37*S26,2) | V26: =ROUND('Workings'!$D$37*S26,2) | W26: =IF(AND(B26="",N(D26)=0),0,IF(OR(C26="",G26=""),1,0)) | X26: =IF(S26>0,COUNTIF(S$22:S26,">0"),0) | Y26: =IF(AND(G26="Estate (residue)",H26<>"Yes",OR(C26="Shares and unit trusts",C26="Other investment",C26="Tax-free investment")),N(D26),0)
J27: =IF(L27=1,M27-N27,"") | L27: =IF(AND(OR(C27="Property",C27="Shares and unit trusts",C27="Other investment",C27="Business interest"),NOT(OR(G27="Spouse",AND(G27="Estate (residue)",'Inputs'!$C$14="Spouse")))),1,0) | M27: =IF(L27=1,N(D27)-N(E27),0) | N27: =IF(AND(L27=1,F27="Yes",M27>0),MIN(M27,'Inputs'!$C$121),0) | O27: =IF(OR(C27="Cash and deposits",H27="Yes"),N(D27),0) | P27: =IF(C27="Property",ROUND('Inputs'!$C$113/100*N(D27),2),0) | Q27: =IF(AND(C27="Property",H27="Yes"),ROUND('Inputs'!$C$114/100*(1+'Inputs'!$C$109/100)*N(D27),2),0) | R27: =IF(G27="Spouse",N(D27),0) | S27: =IF(G27="Named heir",N(D27),0) | T27: =IF(AND(L27=1,N(D27)>0,E27=""),1,0) | U27: =ROUND('Workings'!$C$37*S27,2) | V27: =ROUND('Workings'!$D$37*S27,2) | W27: =IF(AND(B27="",N(D27)=0),0,IF(OR(C27="",G27=""),1,0)) | X27: =IF(S27>0,COUNTIF(S$22:S27,">0"),0) | Y27: =IF(AND(G27="Estate (residue)",H27<>"Yes",OR(C27="Shares and unit trusts",C27="Other investment",C27="Tax-free investment")),N(D27),0)
J28: =IF(L28=1,M28-N28,"") | L28: =IF(AND(OR(C28="Property",C28="Shares and unit trusts",C28="Other investment",C28="Business interest"),NOT(OR(G28="Spouse",AND(G28="Estate (residue)",'Inputs'!$C$14="Spouse")))),1,0) | M28: =IF(L28=1,N(D28)-N(E28),0) | N28: =IF(AND(L28=1,F28="Yes",M28>0),MIN(M28,'Inputs'!$C$121),0) | O28: =IF(OR(C28="Cash and deposits",H28="Yes"),N(D28),0) | P28: =IF(C28="Property",ROUND('Inputs'!$C$113/100*N(D28),2),0) | Q28: =IF(AND(C28="Property",H28="Yes"),ROUND('Inputs'!$C$114/100*(1+'Inputs'!$C$109/100)*N(D28),2),0) | R28: =IF(G28="Spouse",N(D28),0) | S28: =IF(G28="Named heir",N(D28),0) | T28: =IF(AND(L28=1,N(D28)>0,E28=""),1,0) | U28: =ROUND('Workings'!$C$37*S28,2) | V28: =ROUND('Workings'!$D$37*S28,2) | W28: =IF(AND(B28="",N(D28)=0),0,IF(OR(C28="",G28=""),1,0)) | X28: =IF(S28>0,COUNTIF(S$22:S28,">0"),0) | Y28: =IF(AND(G28="Estate (residue)",H28<>"Yes",OR(C28="Shares and unit trusts",C28="Other investment",C28="Tax-free investment")),N(D28),0)
J29: =IF(L29=1,M29-N29,"") | L29: =IF(AND(OR(C29="Property",C29="Shares and unit trusts",C29="Other investment",C29="Business interest"),NOT(OR(G29="Spouse",AND(G29="Estate (residue)",'Inputs'!$C$14="Spouse")))),1,0) | M29: =IF(L29=1,N(D29)-N(E29),0) | N29: =IF(AND(L29=1,F29="Yes",M29>0),MIN(M29,'Inputs'!$C$121),0) | O29: =IF(OR(C29="Cash and deposits",H29="Yes"),N(D29),0) | P29: =IF(C29="Property",ROUND('Inputs'!$C$113/100*N(D29),2),0) | Q29: =IF(AND(C29="Property",H29="Yes"),ROUND('Inputs'!$C$114/100*(1+'Inputs'!$C$109/100)*N(D29),2),0) | R29: =IF(G29="Spouse",N(D29),0) | S29: =IF(G29="Named heir",N(D29),0) | T29: =IF(AND(L29=1,N(D29)>0,E29=""),1,0) | U29: =ROUND('Workings'!$C$37*S29,2) | V29: =ROUND('Workings'!$D$37*S29,2) | W29: =IF(AND(B29="",N(D29)=0),0,IF(OR(C29="",G29=""),1,0)) | X29: =IF(S29>0,COUNTIF(S$22:S29,">0"),0) | Y29: =IF(AND(G29="Estate (residue)",H29<>"Yes",OR(C29="Shares and unit trusts",C29="Other investment",C29="Tax-free investment")),N(D29),0)
J30: =IF(L30=1,M30-N30,"") | L30: =IF(AND(OR(C30="Property",C30="Shares and unit trusts",C30="Other investment",C30="Business interest"),NOT(OR(G30="Spouse",AND(G30="Estate (residue)",'Inputs'!$C$14="Spouse")))),1,0) | M30: =IF(L30=1,N(D30)-N(E30),0) | N30: =IF(AND(L30=1,F30="Yes",M30>0),MIN(M30,'Inputs'!$C$121),0) | O30: =IF(OR(C30="Cash and deposits",H30="Yes"),N(D30),0) | P30: =IF(C30="Property",ROUND('Inputs'!$C$113/100*N(D30),2),0) | Q30: =IF(AND(C30="Property",H30="Yes"),ROUND('Inputs'!$C$114/100*(1+'Inputs'!$C$109/100)*N(D30),2),0) | R30: =IF(G30="Spouse",N(D30),0) | S30: =IF(G30="Named heir",N(D30),0) | T30: =IF(AND(L30=1,N(D30)>0,E30=""),1,0) | U30: =ROUND('Workings'!$C$37*S30,2) | V30: =ROUND('Workings'!$D$37*S30,2) | W30: =IF(AND(B30="",N(D30)=0),0,IF(OR(C30="",G30=""),1,0)) | X30: =IF(S30>0,COUNTIF(S$22:S30,">0"),0) | Y30: =IF(AND(G30="Estate (residue)",H30<>"Yes",OR(C30="Shares and unit trusts",C30="Other investment",C30="Tax-free investment")),N(D30),0)
J31: =IF(L31=1,M31-N31,"") | L31: =IF(AND(OR(C31="Property",C31="Shares and unit trusts",C31="Other investment",C31="Business interest"),NOT(OR(G31="Spouse",AND(G31="Estate (residue)",'Inputs'!$C$14="Spouse")))),1,0) | M31: =IF(L31=1,N(D31)-N(E31),0) | N31: =IF(AND(L31=1,F31="Yes",M31>0),MIN(M31,'Inputs'!$C$121),0) | O31: =IF(OR(C31="Cash and deposits",H31="Yes"),N(D31),0) | P31: =IF(C31="Property",ROUND('Inputs'!$C$113/100*N(D31),2),0) | Q31: =IF(AND(C31="Property",H31="Yes"),ROUND('Inputs'!$C$114/100*(1+'Inputs'!$C$109/100)*N(D31),2),0) | R31: =IF(G31="Spouse",N(D31),0) | S31: =IF(G31="Named heir",N(D31),0) | T31: =IF(AND(L31=1,N(D31)>0,E31=""),1,0) | U31: =ROUND('Workings'!$C$37*S31,2) | V31: =ROUND('Workings'!$D$37*S31,2) | W31: =IF(AND(B31="",N(D31)=0),0,IF(OR(C31="",G31=""),1,0)) | X31: =IF(S31>0,COUNTIF(S$22:S31,">0"),0) | Y31: =IF(AND(G31="Estate (residue)",H31<>"Yes",OR(C31="Shares and unit trusts",C31="Other investment",C31="Tax-free investment")),N(D31),0)
J32: =IF(L32=1,M32-N32,"") | L32: =IF(AND(OR(C32="Property",C32="Shares and unit trusts",C32="Other investment",C32="Business interest"),NOT(OR(G32="Spouse",AND(G32="Estate (residue)",'Inputs'!$C$14="Spouse")))),1,0) | M32: =IF(L32=1,N(D32)-N(E32),0) | N32: =IF(AND(L32=1,F32="Yes",M32>0),MIN(M32,'Inputs'!$C$121),0) | O32: =IF(OR(C32="Cash and deposits",H32="Yes"),N(D32),0) | P32: =IF(C32="Property",ROUND('Inputs'!$C$113/100*N(D32),2),0) | Q32: =IF(AND(C32="Property",H32="Yes"),ROUND('Inputs'!$C$114/100*(1+'Inputs'!$C$109/100)*N(D32),2),0) | R32: =IF(G32="Spouse",N(D32),0) | S32: =IF(G32="Named heir",N(D32),0) | T32: =IF(AND(L32=1,N(D32)>0,E32=""),1,0) | U32: =ROUND('Workings'!$C$37*S32,2) | V32: =ROUND('Workings'!$D$37*S32,2) | W32: =IF(AND(B32="",N(D32)=0),0,IF(OR(C32="",G32=""),1,0)) | X32: =IF(S32>0,COUNTIF(S$22:S32,">0"),0) | Y32: =IF(AND(G32="Estate (residue)",H32<>"Yes",OR(C32="Shares and unit trusts",C32="Other investment",C32="Tax-free investment")),N(D32),0)
J33: =IF(L33=1,M33-N33,"") | L33: =IF(AND(OR(C33="Property",C33="Shares and unit trusts",C33="Other investment",C33="Business interest"),NOT(OR(G33="Spouse",AND(G33="Estate (residue)",'Inputs'!$C$14="Spouse")))),1,0) | M33: =IF(L33=1,N(D33)-N(E33),0) | N33: =IF(AND(L33=1,F33="Yes",M33>0),MIN(M33,'Inputs'!$C$121),0) | O33: =IF(OR(C33="Cash and deposits",H33="Yes"),N(D33),0) | P33: =IF(C33="Property",ROUND('Inputs'!$C$113/100*N(D33),2),0) | Q33: =IF(AND(C33="Property",H33="Yes"),ROUND('Inputs'!$C$114/100*(1+'Inputs'!$C$109/100)*N(D33),2),0) | R33: =IF(G33="Spouse",N(D33),0) | S33: =IF(G33="Named heir",N(D33),0) | T33: =IF(AND(L33=1,N(D33)>0,E33=""),1,0) | U33: =ROUND('Workings'!$C$37*S33,2) | V33: =ROUND('Workings'!$D$37*S33,2) | W33: =IF(AND(B33="",N(D33)=0),0,IF(OR(C33="",G33=""),1,0)) | X33: =IF(S33>0,COUNTIF(S$22:S33,">0"),0) | Y33: =IF(AND(G33="Estate (residue)",H33<>"Yes",OR(C33="Shares and unit trusts",C33="Other investment",C33="Tax-free investment")),N(D33),0)
... J39: =IF(L39=1,M39-N39,"") | L39: =IF(AND(OR(C39="Property",C39="Shares and unit trusts",C39="Other investment",C39="Business interest"),NOT(OR(G39="Spouse",AND(G39="Estate (residue)",'Inputs'!$C$14="Spouse")))),1,0) | M39: =IF(L39=1,N(D39)-N(E39),0) | N39: =IF(AND(L39=1,F39="Yes",M39>0),MIN(M39,'Inputs'!$C$121),0) | O39: =IF(OR(C39="Cash and deposits",H39="Yes"),N(D39),0) | P39: =IF(C39="Property",ROUND('Inputs'!$C$113/100*N(D39),2),0) | Q39: =IF(AND(C39="Property",H39="Yes"),ROUND('Inputs'!$C$114/100*(1+'Inputs'!$C$109/100)*N(D39),2),0) | R39: =IF(G39="Spouse",N(D39),0) | S39: =IF(G39="Named heir",N(D39),0) | T39: =IF(AND(L39=1,N(D39)>0,E39=""),1,0) | U39: =ROUND('Workings'!$C$37*S39,2) | V39: =ROUND('Workings'!$D$37*S39,2) | W39: =IF(AND(B39="",N(D39)=0),0,IF(OR(C39="",G39=""),1,0)) | X39: =IF(S39>0,COUNTIF(S$22:S39,">0"),0) | Y39: =IF(AND(G39="Estate (residue)",H39<>"Yes",OR(C39="Shares and unit trusts",C39="Other investment",C39="Tax-free investment")),N(D39),0)
B40: Base cost: leave it blank only if it is not known; capital gains tax is then worked out on the full value (the worst case) and flagged below. Joint assets: enter your client's share.
B42: 3. Debts
B43: name | D43: amount | I43: notes
B44: Debt | D44: Amount (R) | I44: Notes
B56: 4. Life cover and policies paid out at death
B57: name | C57: paidTo | D57: amount | E57: counted | F57: forWhom | I57: notes
B58: Policy | C58: Paid to | D58: Paid at death (R) | E58: Counted for estate duty? | F58: For whom (a dependant in section 6, or the children's trust) | I58: Notes
L59: =IF(AND(C59="Named person",E59<>"No"),N(D59),0) | M59: =ROUND('Workings'!$C$37*L59,2) | N59: =ROUND('Workings'!$D$37*L59,2) | O59: =IF(L59>0,COUNTIF(S$22:S$39,">0")+COUNTIF(L$59:L59,">0"),0) | P59: 1 | Q59: =IF(AND(F59="The children's trust",C59<>"Estate",C59<>""),1,0) | R59: =IF(L59>0,1,0)
L60: =IF(AND(C60="Named person",E60<>"No"),N(D60),0) | M60: =ROUND('Workings'!$C$37*L60,2) | N60: =ROUND('Workings'!$D$37*L60,2) | O60: =IF(L60>0,COUNTIF(S$22:S$39,">0")+COUNTIF(L$59:L60,">0"),0) | P60: 2 | Q60: =IF(AND(F60="The children's trust",C60<>"Estate",C60<>""),1,0) | R60: =IF(L60>0,1,0)
L61: =IF(AND(C61="Named person",E61<>"No"),N(D61),0) | M61: =ROUND('Workings'!$C$37*L61,2) | N61: =ROUND('Workings'!$D$37*L61,2) | O61: =IF(L61>0,COUNTIF(S$22:S$39,">0")+COUNTIF(L$59:L61,">0"),0) | P61: 3 | Q61: =IF(AND(F61="The children's trust",C61<>"Estate",C61<>""),1,0) | R61: =IF(L61>0,1,0)
L62: =IF(AND(C62="Named person",E62<>"No"),N(D62),0) | M62: =ROUND('Workings'!$C$37*L62,2) | N62: =ROUND('Workings'!$D$37*L62,2) | O62: =IF(L62>0,COUNTIF(S$22:S$39,">0")+COUNTIF(L$59:L62,">0"),0) | P62: 4 | Q62: =IF(AND(F62="The children's trust",C62<>"Estate",C62<>""),1,0) | R62: =IF(L62>0,1,0)
L63: =IF(AND(C63="Named person",E63<>"No"),N(D63),0) | M63: =ROUND('Workings'!$C$37*L63,2) | N63: =ROUND('Workings'!$D$37*L63,2) | O63: =IF(L63>0,COUNTIF(S$22:S$39,">0")+COUNTIF(L$59:L63,">0"),0) | P63: 5 | Q63: =IF(AND(F63="The children's trust",C63<>"Estate",C63<>""),1,0) | R63: =IF(L63>0,1,0)
...

Sheet Summary
B1: Duwalcoe Financial Consultants CC
B2: FSP 9978 | clinton@duwalcoe.co.za | 083 608 5617
B3: =IF(OR(COUNTIF('Inputs'!$B$143:$B$156,"✗ Full FNA*")>0,LEFT('Inputs'!$B$138,1)="✗"),"NOT FOR THE CLIENT: this case needs the full FNA (see Checks on Inputs)","")
B4: Cost of dying
B5: ="Prepared for "&'Inputs'!$C$8&" by "&'Inputs'!$C$10&" · "&IF(ISNUMBER('Inputs'!$C$11),FIXED(DAY('Inputs'!$C$11),0)&" "&CHOOSE(MONTH('Inputs'!$C$11),"January","February","March","April","May","June","July","August","September","October","November","December")&" "&FIXED(YEAR('Inputs'!$C$11),0,TRUE),"")
B7: =IF('Inputs'!$C$15<>"",TRIM('Inputs'!$C$15)&" ","")&"If you died today, winding up your estate would cost about R "&FIXED(('Workings'!$C$56)/1000000,2)&" million"&IF('Workings'!$C$59>0,", and your debts of R "&FIXED(('Workings'!$C$59)/1000000,2)&" million have to be paid too","")&". Your executor would have R "&FIXED(('Workings'!$C$63)/1000000,2)&" million in cash, so "&IF('Workings'!$C$64>0,"would be short by about R "&FIXED(('Workings'!$C$64)/1000000,2)&" million.","would have enough, with about R "&FIXED(ROUND('Workings'!$C$65,-3),0)&" left over.")
B8: =IF(AND(ISNUMBER('Inputs'!$C$100),'Inputs'!$C$100>0),"With a Capital Legacy will and the Legacy Protection Plan, the plan pays about R "&FIXED(ROUND(-'Workings'!$D$57,-3),0)&" of the executor's and conveyancing fees, "&IF('Workings'!$D$64=0,IF('Workings'!$C$64>0,"the shortfall disappears","your executor still has enough"),"the shortfall falls to about R "&FIXED(ROUND('Workings'!$D$64,-3),0))&", and your heirs receive about R "&FIXED(('Workings'!$D$66-'Workings'!$C$66)/1000000,2)&" million more.","")
B10: =IF('Workings'!$C$64>0,"YOUR EXECUTOR'S CASH SHORTFALL TODAY","CASH LEFT OVER FOR YOUR EXECUTOR TODAY")
B11: ="R "&FIXED(ROUND(IF('Workings'!$C$64>0,'Workings'!$C$64,'Workings'!$C$65),-3),0)
B12: =IF('Workings'!$C$64>0,"the cash that has to be found before your estate can be wound up","what is left once the costs are paid")
C14: Today | D14: =IF(AND(ISNUMBER('Inputs'!$C$100),'Inputs'!$C$100>0),"With a Capital Legacy will and the Legacy Protection Plan","Capital Legacy column: enter the quote on Inputs")
B15: Estate duty | C15: ='Workings'!$C$55 | D15: =IF(AND(ISNUMBER('Inputs'!$C$100),'Inputs'!$C$100>0),'Workings'!$D$55,"")
B16: Capital gains tax | C16: ='Workings'!$C$54 | D16: =IF(AND(ISNUMBER('Inputs'!$C$100),'Inputs'!$C$100>0),'Workings'!$D$54,"")
B17: ="Executor's fees"&CHAR(10)&IF(ROUND('Inputs'!$C$108,0)='Inputs'!$C$108,FIXED('Inputs'!$C$108,0),IF(ROUND('Inputs'!$C$108,1)='Inputs'!$C$108,FIXED('Inputs'!$C$108,1),FIXED('Inputs'!$C$108,2)))&"%"&" plus VAT"&IF(AND(ISNUMBER('Inputs'!$C$100),'Inputs'!$C$100>0)," / Capital Legacy "&IF(ROUND('Inputs'!$C$100,0)='Inputs'!$C$100,FIXED('Inputs'!$C$100,0),IF(ROUND('Inputs'!$C$100,1)='Inputs'!$C$100,FIXED('Inputs'!$C$100,1),FIXED('Inputs'!$C$100,2)))&"%"&" plus VAT","") | C17: ='Workings'!$C$51 | D17: =IF(AND(ISNUMBER('Inputs'!$C$100),'Inputs'!$C$100>0),'Workings'!$D$51,"")
B18: ="Property transfer and conveyancing"&CHAR(10)&IF(ROUND('Inputs'!$C$113,0)='Inputs'!$C$113,FIXED('Inputs'!$C$113,0),IF(ROUND('Inputs'!$C$113,1)='Inputs'!$C$113,FIXED('Inputs'!$C$113,1),FIXED('Inputs'!$C$113,2)))&"%"&" of value"&IF(AND(ISNUMBER('Inputs'!$C$100),'Inputs'!$C$100>0)," / Capital Legacy's estimate","") | C18: ='Workings'!$C$52 | D18: =IF(AND(ISNUMBER('Inputs'!$C$100),'Inputs'!$C$100>0),'Workings'!$D$52,"")
B19: Agent's commission | C19: ='Workings'!$C$53 | D19: =IF(AND(ISNUMBER('Inputs'!$C$100),'Inputs'!$C$100>0),'Workings'!$D$53,"")
B20: Funeral, Master's fees and sundries | C20: ='Workings'!$C$50 | D20: =IF(AND(ISNUMBER('Inputs'!$C$100),'Inputs'!$C$100>0),'Workings'!$D$50,"")
B21: Cost of winding up | C21: ='Workings'!$C$56 | D21: =IF(AND(ISNUMBER('Inputs'!$C$100),'Inputs'!$C$100>0),'Workings'!$D$56,"")
B22: Paid by the Legacy plan | C22: =-'Workings'!$C$57 | D22: =IF(AND(ISNUMBER('Inputs'!$C$100),'Inputs'!$C$100>0),-'Workings'!$D$57,"")
B23: Paid by your estate | C23: ='Workings'!$C$58 | D23: =IF(AND(ISNUMBER('Inputs'!$C$100),'Inputs'!$C$100>0),'Workings'!$D$58,"")
B24: Debts | C24: ='Workings'!$C$59 | D24: =IF(AND(ISNUMBER('Inputs'!$C$100),'Inputs'!$C$100>0),'Workings'!$D$59,"")
B25: ="Cash your executor has"&CHAR(10)&"bank accounts, deposits and investments cashed in" | C25: ='Workings'!$C$63 | D25: =IF(AND(ISNUMBER('Inputs'!$C$100),'Inputs'!$C$100>0),'Workings'!$D$63,"")
B26: Shortfall, or cash left over | C26: =IF('Workings'!$C$64>0,"Short R "&FIXED(ROUND('Workings'!$C$64,-3),0),"Covered: R "&FIXED(ROUND('Workings'!$C$65,-3),0)&" left over") | D26: =IF(AND(ISNUMBER('Inputs'!$C$100),'Inputs'!$C$100>0),IF('Workings'!$D$64>0,"Short R "&FIXED(ROUND('Workings'!$D$64,-3),0),"Covered: R "&FIXED(ROUND('Workings'!$D$65,-3),0)&" left over"),"")
B27: =IF(OR(SUM('Inputs'!$R$22:$R$39)>0,'Inputs'!$C$14="Spouse"),"Left for your spouse and heirs","Left for your heirs")&CHAR(10)&"if they pay any shortfall in" | C27: ='Workings'!$C$66 | D27: =IF(AND(ISNUMBER('Inputs'!$C$100),'Inputs'!$C$100>0),'Workings'!$D$66,"")
B28: Cost to you | C28: None | D28: =IF(AND(ISNUMBER('Inputs'!$C$100),'Inputs'!$C$100>0),IF(ISNUMBER('Inputs'!$C$104),"From R "&FIXED('Inputs'!$C$104,2)&" a month","Premium: enter it on Inputs"),"")
B29: =IF('Workings'!$C$45<0,"The people you leave policies or bequests to directly pay R "&FIXED(-'Workings'!$C$45,0)&" of the estate duty themselves; your executor recovers it from them and it is not in the cost above. If it cannot be recovered, your estate pays it.","")
B31: Next steps to discuss
B32: ="1. Sign a new will that says what you want"&IF(AND(ISNUMBER('Inputs'!$C$100),'Inputs'!$C$100>0),", with Capital Legacy as your executor","")&". Until you do, your current will, or the law if you have none, decides who inherits."
B33: ="2. "&IF('Workings'!$C$64>0,"Decide how your executor will find the cash: "&IF(AND(ISNUMBER('Inputs'!$C$100),'Inputs'!$C$100>0),"the Legacy Protection Plan, ","")&"a property sold, or your heirs paying it in.","Keep enough cash for your executor: today there is enough, with about R "&FIXED(ROUND('Workings'!$C$65,-3),0)&" to spare.")
B34: ="3. Remember that your savings are your executor's cash. Every R 1 spent from them "&IF('Workings'!$C$64>0,"adds about "&ROUND(100*(1-'Inputs'!$C$108/100*(1+'Inputs'!$C$109/100))*IF('Workings'!$C$35>0,1-'Inputs'!$C$116/100,1),0)&" cents to the shortfall.","takes about "&ROUND(100*(1-'Inputs'!$C$108/100*(1+'Inputs'!$C$109/100))*IF('Workings'!$C$35>0,1-'Inputs'!$C$116/100,1),0)&" cents off what your executor has spare.")
B36: ="Basis: indicative and worst case, based on your instructed wishes, not a signed will, and on the values you gave us"&IF(ISNUMBER('Inputs'!$C$12)," on "&FIXED(DAY('Inputs'!$C$12),0)&" "&CHOOSE(MONTH('Inputs'!$C$12),"January","February","March","April","May","June","July","August","September","October","November","December")&" "&FIXED(YEAR('Inputs'!$C$12),0,TRUE),"")&". Our standard assumptions are on the Workings page."&IF(AND(ISNUMBER('Inputs'!$C$100),'Inputs'!$C$100>0)," Capital Legacy quote "&'Inputs'!$C$99&"; premiums rise each year and are not guaranteed.","")&" Figures are for your death today. Not legal or tax advice; the executor's actual costs may differ."

Sheet Life cover need
B1: Duwalcoe Financial Consultants CC
B2: FSP 9978 | clinton@duwalcoe.co.za | 083 608 5617
B3: =IF(OR(COUNTIF('Inputs'!$B$143:$B$156,"✗ Full FNA*")>0,LEFT('Inputs'!$B$138,1)="✗"),"NOT FOR THE CLIENT: this case needs the full FNA (see Checks on Inputs)","")
B4: Life cover need
B5: ="Prepared for "&'Inputs'!$C$8&" by "&'Inputs'!$C$10&" · "&IF(ISNUMBER('Inputs'!$C$11),FIXED(DAY('Inputs'!$C$11),0)&" "&CHOOSE(MONTH('Inputs'!$C$11),"January","February","March","April","May","June","July","August","September","October","November","December")&" "&FIXED(YEAR('Inputs'!$C$11),0,TRUE),"")
B7: =IF(COUNTIF('Inputs'!$B$89:$B$94,"?*")=0,"No one who depends on you is recorded, so there is no income need to cover.","If you died today, "&IF((('Needs calc'!$C$51>0)+('Needs calc'!$C$58>0)+('Needs calc'!$C$65>0)+('Needs calc'!$C$72>0)+('Needs calc'!$C$79>0)+('Needs calc'!$C$86>0)+('Needs calc'!$C$91>0))=0,"everyone who depends on you would have the income you want for them"&IF('Needs calc'!$C$4=1,", with the trust sharing by need as one family pot","")&".",IF('Needs calc'!$C$51>0,'Inputs'!$B$89&" would have about R "&FIXED(ROUND('Needs calc'!$C$52,-2),0)&" a month of the R "&FIXED(ROUND('Inputs'!$E$89,-2),0)&" you want. ","")&IF('Needs calc'!$C$58>0,'Inputs'!$B$90&" would have about R "&FIXED(ROUND('Needs calc'!$C$59,-2),0)&" a month of the R "&FIXED(ROUND('Inputs'!$E$90,-2),0)&" you want. ","")&IF('Needs calc'!$C$65>0,'Inputs'!$B$91&" would have about R "&FIXED(ROUND('Needs calc'!$C$66,-2),0)&" a month of the R "&FIXED(ROUND('Inputs'!$E$91,-2),0)&" you want. ","")&IF('Needs calc'!$C$72>0,'Inputs'!$B$92&" would have about R "&FIXED(ROUND('Needs calc'!$C$73,-2),0)&" a month of the R "&FIXED(ROUND('Inputs'!$E$92,-2),0)&" you want. ","")&IF('Needs calc'!$C$79>0,'Inputs'!$B$93&" would have about R "&FIXED(ROUND('Needs calc'!$C$80,-2),0)&" a month of the R "&FIXED(ROUND('Inputs'!$E$93,-2),0)&" you want. ","")&IF('Needs calc'!$C$86>0,'Inputs'!$B$94&" would have about R "&FIXED(ROUND('Needs calc'!$C$87,-2),0)&" a month of the R "&FIXED(ROUND('Inputs'!$E$94,-2),0)&" you want. ","")&IF('Needs calc'!$C$91>0,"The family pot would be short by R "&FIXED(ROUND('Needs calc'!$C$91,-3),0)&". ","")&IF((('Needs calc'!$C$51>0)+('Needs calc'!$C$58>0)+('Needs calc'!$C$65>0)+('Needs calc'!$C$72>0)+('Needs calc'!$C$79>0)+('Needs calc'!$C$86>0)+('Needs calc'!$C$91>0))<COUNTIF('Inputs'!$B$89:$B$94,"?*"),"Everyone else is provided for.","")))
B8: =IF('Workings'!$C$64>0,"Your estate itself would be short of cash by about R "&FIXED(ROUND('Workings'!$C$64,-3),0)&" to pay its debts and costs.","Your estate itself has enough cash to pay its debts and costs, with about R "&FIXED(ROUND('Workings'!$C$65,-3),0)&" left over for your heirs.")
B10: =IF(('Needs calc'!$T$7+'Needs calc'!$T$8+'Needs calc'!$T$9+'Needs calc'!$T$10+'Needs calc'!$T$11+'Needs calc'!$T$12+'Needs calc'!$T$13)>0,"LIFE COVER TO CLOSE THE GAPS","EVERYONE WHO DEPENDS ON YOU IS PROVIDED FOR")
B11: =IF(('Needs calc'!$T$7+'Needs calc'!$T$8+'Needs calc'!$T$9+'Needs calc'!$T$10+'Needs calc'!$T$11+'Needs calc'!$T$12+'Needs calc'!$T$13)>0,"R "&FIXED(ROUND(('Needs calc'!$T$7+'Needs calc'!$T$8+'Needs calc'!$T$9+'Needs calc'!$T$10+'Needs calc'!$T$11+'Needs calc'!$T$12+'Needs calc'!$T$13),-3),0),"No new cover needed")
B12: =IF(('Needs calc'!$T$7+'Needs calc'!$T$8+'Needs calc'!$T$9+'Needs calc'!$T$10+'Needs calc'!$T$11+'Needs calc'!$T$12+'Needs calc'!$T$13)>0,"new cover nominated for the people who are short, after the estate duty it brings","on the needs you gave us, as your policies and will instructions stand today")
B14: Your estate (the cost of dying)
B15: Cash the executor needs | C15: ='Workings'!$C$60
B16: Cash the executor has | C16: ='Workings'!$C$63
B17: Result | C17: =IF('Workings'!$C$64>0,"Short R "&FIXED(ROUND('Workings'!$C$64,-3),0)&". To close it: R "&FIXED(ROUND('Needs years'!$C$377,-3),0)&" of cover paid to your estate"&IF(OR(LEFT('Inputs'!$C$13,7)="Married",'Inputs'!$C$13="Life partner",'Inputs'!$C$13="Civil Union")," or R "&FIXED(ROUND('Workings'!$C$64,-3),0)&" nominated to your spouse, who pays it in","")&".","Covered: R "&FIXED(ROUND('Workings'!$C$65,-3),0)&" left for your heirs")
B19: The people who depend on you | C19: =IF('Inputs'!$B$89="","",'Inputs'!$B$89) | D19: =IF('Inputs'!$B$90="","",'Inputs'!$B$90) | E19: =IF('Inputs'!$B$91="","",'Inputs'!$B$91) | F19: =IF('Inputs'!$B$92="","",'Inputs'!$B$92)
B20: You want for them, a month | C20: =IF('Inputs'!$B$89="","",N('Inputs'!$E$89)) | D20: =IF('Inputs'!$B$90="","",N('Inputs'!$E$90)) | E20: =IF('Inputs'!$B$91="","",N('Inputs'!$E$91)) | F20: =IF('Inputs'!$B$92="","",N('Inputs'!$E$92))
B21: For | C21: =IF('Inputs'!$B$89="","",'Needs years'!$C$8&" years") | D21: =IF('Inputs'!$B$90="","",'Needs years'!$C$64&" years") | E21: =IF('Inputs'!$B$91="","",'Needs years'!$C$120&" years") | F21: =IF('Inputs'!$B$92="","",'Needs years'!$C$176&" years")
B22: Rising each year by | C22: =IF('Inputs'!$B$89="","",'Needs years'!$C$10) | D22: =IF('Inputs'!$B$90="","",'Needs years'!$C$66) | E22: =IF('Inputs'!$B$91="","",'Needs years'!$C$122) | F22: =IF('Inputs'!$B$92="","",'Needs years'!$C$178)
B23: Capital needed today | C23: =IF('Inputs'!$B$89="","",IF(AND('Needs calc'!$C$4=1,'Inputs'!$Q$89=1),'Needs calc'!$C$50,'Needs years'!$C$7+'Needs calc'!$C$50)) | D23: =IF('Inputs'!$B$90="","",IF(AND('Needs calc'!$C$4=1,'Inputs'!$Q$90=1),'Needs calc'!$C$57,'Needs years'!$C$63+'Needs calc'!$C$57)) | E23: =IF('Inputs'!$B$91="","",IF(AND('Needs calc'!$C$4=1,'Inputs'!$Q$91=1),'Needs calc'!$C$64,'Needs years'!$C$119+'Needs calc'!$C$64)) | F23: =IF('Inputs'!$B$92="","",IF(AND('Needs calc'!$C$4=1,'Inputs'!$Q$92=1),'Needs calc'!$C$71,'Needs years'!$C$175+'Needs calc'!$C$71))
B24: Retirement money (a living annuity for them) | C24: =IF('Inputs'!$B$89="","",'Needs years'!$C$7) | D24: =IF('Inputs'!$B$90="","",'Needs years'!$C$63) | E24: =IF('Inputs'!$B$91="","",'Needs years'!$C$119) | F24: =IF('Inputs'!$B$92="","",'Needs years'!$C$175)
B25: From your estate, policies and the trust | C25: =IF('Inputs'!$B$89="","",'Needs calc'!$C$46) | D25: =IF('Inputs'!$B$90="","",'Needs calc'!$C$53) | E25: =IF('Inputs'!$B$91="","",'Needs calc'!$C$60) | F25: =IF('Inputs'!$B$92="","",'Needs calc'!$C$67)
B26: Capital in place | C26: =IF('Inputs'!$B$89="","",IF(AND('Needs calc'!$C$4=1,'Inputs'!$Q$89=1),'Needs calc'!$C$50,'Needs years'!$C$7+'Needs calc'!$C$46)) | D26: =IF('Inputs'!$B$90="","",IF(AND('Needs calc'!$C$4=1,'Inputs'!$Q$90=1),'Needs calc'!$C$57,'Needs years'!$C$63+'Needs calc'!$C$53)) | E26: =IF('Inputs'!$B$91="","",IF(AND('Needs calc'!$C$4=1,'Inputs'!$Q$91=1),'Needs calc'!$C$64,'Needs years'!$C$119+'Needs calc'!$C$60)) | F26: =IF('Inputs'!$B$92="","",IF(AND('Needs calc'!$C$4=1,'Inputs'!$Q$92=1),'Needs calc'!$C$71,'Needs years'!$C$175+'Needs calc'!$C$67))
B27: Monthly income it pays | C27: =IF('Inputs'!$B$89="","",'Needs calc'!$C$52) | D27: =IF('Inputs'!$B$90="","",'Needs calc'!$C$59) | E27: =IF('Inputs'!$B$91="","",'Needs calc'!$C$66) | F27: =IF('Inputs'!$B$92="","",'Needs calc'!$C$73)
B28: Shortfall, or over | C28: =IF('Inputs'!$B$89="","",IF(AND('Needs calc'!$C$4=1,'Inputs'!$Q$89=1),IF('Needs calc'!$C$90>=0,"Covered by the pot","Pot short"),IF('Needs calc'!$C$51>0,"Short R "&FIXED(ROUND('Needs calc'!$C$51,-3),0),IF('Needs calc'!$C$51<0,"R "&FIXED(ROUND(-'Needs calc'!$C$51,-3),0)&" over","Covered")))) | D28: =IF('Inputs'!$B$90="","",IF(AND('Needs calc'!$C$4=1,'Inputs'!$Q$90=1),IF('Needs calc'!$C$90>=0,"Covered by the pot","Pot short"),IF('Needs calc'!$C$58>0,"Short R "&FIXED(ROUND('Needs calc'!$C$58,-3),0),IF('Needs calc'!$C$58<0,"R "&FIXED(ROUND(-'Needs calc'!$C$58,-3),0)&" over","Covered")))) | E28: =IF('Inputs'!$B$91="","",IF(AND('Needs calc'!$C$4=1,'Inputs'!$Q$91=1),IF('Needs calc'!$C$90>=0,"Covered by the pot","Pot short"),IF('Needs calc'!$C$65>0,"Short R "&FIXED(ROUND('Needs calc'!$C$65,-3),0),IF('Needs calc'!$C$65<0,"R "&FIXED(ROUND(-'Needs calc'!$C$65,-3),0)&" over","Covered")))) | F28: =IF('Inputs'!$B$92="","",IF(AND('Needs calc'!$C$4=1,'Inputs'!$Q$92=1),IF('Needs calc'!$C$90>=0,"Covered by the pot","Pot short"),IF('Needs calc'!$C$72>0,"Short R "&FIXED(ROUND('Needs calc'!$C$72,-3),0),IF('Needs calc'!$C$72<0,"R "&FIXED(ROUND(-'Needs calc'!$C$72,-3),0)&" over","Covered"))))
B29: New life cover to close the gap | C29: =IF('Inputs'!$B$89="","",IF('Needs calc'!$T$7>0,'Needs calc'!$T$7,"None needed")) | D29: =IF('Inputs'!$B$90="","",IF('Needs calc'!$T$8>0,'Needs calc'!$T$8,"None needed")) | E29: =IF('Inputs'!$B$91="","",IF('Needs calc'!$T$9>0,'Needs calc'!$T$9,"None needed")) | F29: =IF('Inputs'!$B$92="","",IF('Needs calc'!$T$10>0,'Needs calc'!$T$10,"None needed"))
B30: =IF('Needs calc'!$C$4=1,"The trust shares by need as one family pot: R "&FIXED(ROUND('Needs calc'!$C$88,-3),0)&" in the pot, R "&FIXED(ROUND('Needs calc'!$C$89,-3),0)&" needed for the children, "&IF('Needs calc'!$C$90>=0,"R "&FIXED(ROUND('Needs calc'!$C$90,-3),0)&" left to share equally at the end.","short by R "&FIXED(ROUND(-'Needs calc'!$C$90,-3),0)&"."),"")&IF(COUNTIF('Inputs'!$B$89:$B$94,"?*")>4," The others who depend on you are on the workings page.","")
B31: =IF('Needs calc'!$C$44>0,"Life cover of R "&FIXED(ROUND('Needs calc'!$C$44,-3),0)&" is paid directly to "&IF(SUMPRODUCT('Inputs'!$R$59:$R$70*('Inputs'!$F$59:$F$70="")*('Inputs'!$D$59:$D$70>0))=1,"someone who is","people who are")&" not recorded as depending on you; they pay R "&FIXED(ROUND('Needs calc'!$C$45,-3),0)&" of the estate duty on it, and it is not counted for anyone above.","")
B33: =IF(SUMPRODUCT(('Inputs'!$H$89:$H$94="Yes")*('Inputs'!$B$89:$B$94<>""))>0,"What the trust will cost (trustee fees of "&IF(ROUND('Inputs'!$H$108,0)='Inputs'!$H$108,FIXED('Inputs'!$H$108,0),IF(ROUND('Inputs'!$H$108,1)='Inputs'!$H$108,FIXED('Inputs'!$H$108,1),FIXED('Inputs'!$H$108,2)))&"%"&" a year)","") | C33: =IF('Inputs'!$H$89="Yes",'Inputs'!$B$89,"") | D33: =IF('Inputs'!$H$90="Yes",'Inputs'!$B$90,"") | E33: =IF('Inputs'!$H$91="Yes",'Inputs'!$B$91,"") | F33: =IF('Inputs'!$H$92="Yes",'Inputs'!$B$92,"")
B34: =IF(SUMPRODUCT(('Inputs'!$H$89:$H$94="Yes")*('Inputs'!$B$89:$B$94<>""))>0,"First year","") | C34: =IF('Inputs'!$H$89="Yes",'Needs years'!$C$17,"") | D34: =IF('Inputs'!$H$90="Yes",'Needs years'!$C$73,"") | E34: =IF('Inputs'!$H$91="Yes",'Needs years'!$C$129,"") | F34: =IF('Inputs'!$H$92="Yes",'Needs years'!$C$185,"")
B35: =IF(SUMPRODUCT(('Inputs'!$H$89:$H$94="Yes")*('Inputs'!$B$89:$B$94<>""))>0,"Over the whole period","") | C35: =IF('Inputs'!$H$89="Yes",'Needs years'!$C$18,"") | D35: =IF('Inputs'!$H$90="Yes",'Needs years'!$C$74,"") | E35: =IF('Inputs'!$H$91="Yes",'Needs years'!$C$130,"") | F35: =IF('Inputs'!$H$92="Yes",'Needs years'!$C$186,"")
B36: =IF(SUMPRODUCT(('Inputs'!$H$89:$H$94="Yes")*('Inputs'!$B$89:$B$94<>""))>0,"Extra capital it needs today (already in the need)","") | C36: =IF('Inputs'!$H$89="Yes",'Needs years'!$C$19,"") | D36: =IF('Inputs'!$H$90="Yes",'Needs years'!$C$75,"") | E36: =IF('Inputs'!$H$91="Yes",'Needs years'!$C$131,"") | F36: =IF('Inputs'!$H$92="Yes",'Needs years'!$C$187,"")
B38: Next steps to discuss
B39: ="1. "&IF(('Needs calc'!$T$7+'Needs calc'!$T$8+'Needs calc'!$T$9+'Needs calc'!$T$10+'Needs calc'!$T$11+'Needs calc'!$T$12+'Needs calc'!$T$13)>0,"Close the gap: the Options page shows the ways to do it, starting with what you already have.","Keep your nominations and will instructions as they are: they provide for everyone today.")
B40: 2. Check who each of your policies and retirement funds pays to: the nominations decide who receives the money, not your will.
B41: ="3. "&IF(SUMPRODUCT(('Inputs'!$H$89:$H$94="Yes")*('Inputs'!$B$89:$B$94<>""))>0,"Decide how the trust in your will shares between the children: equal shares, or one family pot shared by need.","Sign a will that says who inherits, so the law does not decide it for you.")
B43: ="Basis: indicative, on the needs you gave us and your policies and will instructions as they stand. Capital for a dependant is invested at "&FIXED('Inputs'!$C$122,0)&"% a year before tax as a unit trust, less tax"&IF(SUMPRODUCT(('Inputs'!$H$89:$H$94="Yes")*('Inputs'!$B$89:$B$94<>""))>0," and trustee fees of "&IF(ROUND('Inputs'!$H$108,0)='Inputs'!$H$108,FIXED('Inputs'!$H$108,0),IF(ROUND('Inputs'!$H$108,1)='Inputs'!$H$108,FIXED('Inputs'!$H$108,1),FIXED('Inputs'!$H$108,2)))&"%"&" a year while it is in the trust","")&"; retirement money paid to a dependant pays them first from a living annuity, taxed as their income. Each need rises as you asked. Not legal or tax advice."

Sheet Options
B1: Duwalcoe Financial Consultants CC
B2: FSP 9978 | clinton@duwalcoe.co.za | 083 608 5617
B3: =IF(OR(COUNTIF('Inputs'!$B$143:$B$156,"✗ Full FNA*")>0,LEFT('Inputs'!$B$138,1)="✗"),"NOT FOR THE CLIENT: this case needs the full FNA (see Checks on Inputs)","")
B4: Options to discuss
B5: Change a yellow cell and the whole column works itself out again, estate duty included.
B6: =IF((('Needs calc'!$C$51>0)+('Needs calc'!$C$58>0)+('Needs calc'!$C$65>0)+('Needs calc'!$C$72>0)+('Needs calc'!$C$79>0)+('Needs calc'!$C$86>0)+('Needs calc'!$C$91>0))=0,"Everyone who depends on you is provided for today. These options show what changes would do.","Your estate"&IF('Workings'!$C$64>0," is short of cash, and some of the people who depend on you are short."," can pay its bills. The question is how to make sure the people who depend on you have the income you want for them."))
C8: Today | D8: Option 1 | E8: Option 2 | F8: Option 3
B9: How the trust shares | C9: =IF('Needs calc'!$C$4=1,"One family pot",IF('Needs calc'!$C$29>0,"Equal shares","")) | D9: One family pot | E9: Equal shares | F9: Equal shares
B10: Close the gaps with | C10: Nothing | D10: Nothing | E10: Part of a nomination | F10: New life cover
B11: Nomination to use
B12: Moved to (for "All of a nomination") | D12: The children's trust
B13: What changes | C13: Nothing | D13: =IF('Needs calc'!$AK$18=1,"Choose a policy paid to a person or the spouse, not to the estate",IF('Needs calc'!$AK$100=1,"Not enough in that nomination to close the gaps",CHOOSE('Needs calc'!$AK$3+1,"No change to the policies","New cover of R "&FIXED(ROUND('Needs calc'!$AK$15,-3),0)&" nominated for those who are short","R "&FIXED(ROUND('Needs calc'!$AK$14,-3),0)&" of "&'Options'!$D$11&" moved to those who are short","All of "&'Options'!$D$11&" (R "&FIXED(ROUND('Needs calc'!$AK$14,-3),0)&") moved to "&'Options'!$D$12)&IF('Needs calc'!$AK$4=1,"; the trust shares by need as one family pot",""))) | E13: =IF('Needs calc'!$BB$18=1,"Choose a policy paid to a person or the spouse, not to the estate",IF('Needs calc'!$BB$100=1,"Not enough in that nomination to close the gaps",CHOOSE('Needs calc'!$BB$3+1,"No change to the policies","New cover of R "&FIXED(ROUND('Needs calc'!$BB$15,-3),0)&" nominated for those who are short","R "&FIXED(ROUND('Needs calc'!$BB$14,-3),0)&" of "&'Options'!$E$11&" moved to those who are short","All of "&'Options'!$E$11&" (R "&FIXED(ROUND('Needs calc'!$BB$14,-3),0)&") moved to "&'Options'!$E$12)&IF('Needs calc'!$BB$4=1,"; the trust shares by need as one family pot",""))) | F13: =IF('Needs calc'!$BS$18=1,"Choose a policy paid to a person or the spouse, not to the estate",IF('Needs calc'!$BS$100=1,"Not enough in that nomination to close the gaps",CHOOSE('Needs calc'!$BS$3+1,"No change to the policies","New cover of R "&FIXED(ROUND('Needs calc'!$BS$15,-3),0)&" nominated for those who are short","R "&FIXED(ROUND('Needs calc'!$BS$14,-3),0)&" of "&'Options'!$F$11&" moved to those who are short","All of "&'Options'!$F$11&" (R "&FIXED(ROUND('Needs calc'!$BS$14,-3),0)&") moved to "&'Options'!$F$12)&IF('Needs calc'!$BS$4=1,"; the trust shares by need as one family pot","")))
B15: What it does
B16: =IF('Inputs'!$B$89="","",'Inputs'!$B$89&": capital set aside") | C16: =IF('Inputs'!$B$89="","",'Needs years'!$C$7+IF(AND('Needs calc'!$C$4=1,'Inputs'!$Q$89=1),'Needs calc'!$C$50,'Needs calc'!$C$46)) | D16: =IF('Inputs'!$B$89="","",'Needs years'!$C$7+IF(AND('Needs calc'!$AK$4=1,'Inputs'!$Q$89=1),'Needs calc'!$AK$50,'Needs calc'!$AK$46)) | E16: =IF('Inputs'!$B$89="","",'Needs years'!$C$7+IF(AND('Needs calc'!$BB$4=1,'Inputs'!$Q$89=1),'Needs calc'!$BB$50,'Needs calc'!$BB$46)) | F16: =IF('Inputs'!$B$89="","",'Needs years'!$C$7+IF(AND('Needs calc'!$BS$4=1,'Inputs'!$Q$89=1),'Needs calc'!$BS$50,'Needs calc'!$BS$46))
B17: =IF('Inputs'!$B$89="","",'Inputs'!$B$89&": a month") | C17: =IF('Inputs'!$B$89="","",'Needs calc'!$C$52) | D17: =IF('Inputs'!$B$89="","",'Needs calc'!$AK$52) | E17: =IF('Inputs'!$B$89="","",'Needs calc'!$BB$52) | F17: =IF('Inputs'!$B$89="","",'Needs calc'!$BS$52)
B18: =IF('Inputs'!$B$89="","",'Inputs'!$B$89) | C18: =IF('Inputs'!$B$89="","",IF(AND('Needs calc'!$C$4=1,'Inputs'!$Q$89=1),IF('Needs calc'!$C$90>=0,"Covered","Pot short R "&FIXED(ROUND(-'Needs calc'!$C$90,-3),0)),IF('Needs calc'!$C$51>0,"Short R "&FIXED(ROUND('Needs calc'!$C$51,-3),0),IF('Needs calc'!$C$51<0,"R "&FIXED(ROUND(-'Needs calc'!$C$51,-3),0)&" over","Covered")))) | D18: =IF('Inputs'!$B$89="","",IF(AND('Needs calc'!$AK$4=1,'Inputs'!$Q$89=1),IF('Needs calc'!$AK$90>=0,"Covered","Pot short R "&FIXED(ROUND(-'Needs calc'!$AK$90,-3),0)),IF('Needs calc'!$AK$51>0,"Short R "&FIXED(ROUND('Needs calc'!$AK$51,-3),0),IF('Needs calc'!$AK$51<0,"R "&FIXED(ROUND(-'Needs calc'!$AK$51,-3),0)&" over","Covered")))) | E18: =IF('Inputs'!$B$89="","",IF(AND('Needs calc'!$BB$4=1,'Inputs'!$Q$89=1),IF('Needs calc'!$BB$90>=0,"Covered","Pot short R "&FIXED(ROUND(-'Needs calc'!$BB$90,-3),0)),IF('Needs calc'!$BB$51>0,"Short R "&FIXED(ROUND('Needs calc'!$BB$51,-3),0),IF('Needs calc'!$BB$51<0,"R "&FIXED(ROUND(-'Needs calc'!$BB$51,-3),0)&" over","Covered")))) | F18: =IF('Inputs'!$B$89="","",IF(AND('Needs calc'!$BS$4=1,'Inputs'!$Q$89=1),IF('Needs calc'!$BS$90>=0,"Covered","Pot short R "&FIXED(ROUND(-'Needs calc'!$BS$90,-3),0)),IF('Needs calc'!$BS$51>0,"Short R "&FIXED(ROUND('Needs calc'!$BS$51,-3),0),IF('Needs calc'!$BS$51<0,"R "&FIXED(ROUND(-'Needs calc'!$BS$51,-3),0)&" over","Covered"))))
B19: =IF('Inputs'!$B$90="","",'Inputs'!$B$90&": capital set aside") | C19: =IF('Inputs'!$B$90="","",'Needs years'!$C$63+IF(AND('Needs calc'!$C$4=1,'Inputs'!$Q$90=1),'Needs calc'!$C$57,'Needs calc'!$C$53)) | D19: =IF('Inputs'!$B$90="","",'Needs years'!$C$63+IF(AND('Needs calc'!$AK$4=1,'Inputs'!$Q$90=1),'Needs calc'!$AK$57,'Needs calc'!$AK$53)) | E19: =IF('Inputs'!$B$90="","",'Needs years'!$C$63+IF(AND('Needs calc'!$BB$4=1,'Inputs'!$Q$90=1),'Needs calc'!$BB$57,'Needs calc'!$BB$53)) | F19: =IF('Inputs'!$B$90="","",'Needs years'!$C$63+IF(AND('Needs calc'!$BS$4=1,'Inputs'!$Q$90=1),'Needs calc'!$BS$57,'Needs calc'!$BS$53))
B20: =IF('Inputs'!$B$90="","",'Inputs'!$B$90&": a month") | C20: =IF('Inputs'!$B$90="","",'Needs calc'!$C$59) | D20: =IF('Inputs'!$B$90="","",'Needs calc'!$AK$59) | E20: =IF('Inputs'!$B$90="","",'Needs calc'!$BB$59) | F20: =IF('Inputs'!$B$90="","",'Needs calc'!$BS$59)
B21: =IF('Inputs'!$B$90="","",'Inputs'!$B$90) | C21: =IF('Inputs'!$B$90="","",IF(AND('Needs calc'!$C$4=1,'Inputs'!$Q$90=1),IF('Needs calc'!$C$90>=0,"Covered","Pot short R "&FIXED(ROUND(-'Needs calc'!$C$90,-3),0)),IF('Needs calc'!$C$58>0,"Short R "&FIXED(ROUND('Needs calc'!$C$58,-3),0),IF('Needs calc'!$C$58<0,"R "&FIXED(ROUND(-'Needs calc'!$C$58,-3),0)&" over","Covered")))) | D21: =IF('Inputs'!$B$90="","",IF(AND('Needs calc'!$AK$4=1,'Inputs'!$Q$90=1),IF('Needs calc'!$AK$90>=0,"Covered","Pot short R "&FIXED(ROUND(-'Needs calc'!$AK$90,-3),0)),IF('Needs calc'!$AK$58>0,"Short R "&FIXED(ROUND('Needs calc'!$AK$58,-3),0),IF('Needs calc'!$AK$58<0,"R "&FIXED(ROUND(-'Needs calc'!$AK$58,-3),0)&" over","Covered")))) | E21: =IF('Inputs'!$B$90="","",IF(AND('Needs calc'!$BB$4=1,'Inputs'!$Q$90=1),IF('Needs calc'!$BB$90>=0,"Covered","Pot short R "&FIXED(ROUND(-'Needs calc'!$BB$90,-3),0)),IF('Needs calc'!$BB$58>0,"Short R "&FIXED(ROUND('Needs calc'!$BB$58,-3),0),IF('Needs calc'!$BB$58<0,"R "&FIXED(ROUND(-'Needs calc'!$BB$58,-3),0)&" over","Covered")))) | F21: =IF('Inputs'!$B$90="","",IF(AND('Needs calc'!$BS$4=1,'Inputs'!$Q$90=1),IF('Needs calc'!$BS$90>=0,"Covered","Pot short R "&FIXED(ROUND(-'Needs calc'!$BS$90,-3),0)),IF('Needs calc'!$BS$58>0,"Short R "&FIXED(ROUND('Needs calc'!$BS$58,-3),0),IF('Needs calc'!$BS$58<0,"R "&FIXED(ROUND(-'Needs calc'!$BS$58,-3),0)&" over","Covered"))))
B22: =IF('Inputs'!$B$91="","",'Inputs'!$B$91&": capital set aside") | C22: =IF('Inputs'!$B$91="","",'Needs years'!$C$119+IF(AND('Needs calc'!$C$4=1,'Inputs'!$Q$91=1),'Needs calc'!$C$64,'Needs calc'!$C$60)) | D22: =IF('Inputs'!$B$91="","",'Needs years'!$C$119+IF(AND('Needs calc'!$AK$4=1,'Inputs'!$Q$91=1),'Needs calc'!$AK$64,'Needs calc'!$AK$60)) | E22: =IF('Inputs'!$B$91="","",'Needs years'!$C$119+IF(AND('Needs calc'!$BB$4=1,'Inputs'!$Q$91=1),'Needs calc'!$BB$64,'Needs calc'!$BB$60)) | F22: =IF('Inputs'!$B$91="","",'Needs years'!$C$119+IF(AND('Needs calc'!$BS$4=1,'Inputs'!$Q$91=1),'Needs calc'!$BS$64,'Needs calc'!$BS$60))
B23: =IF('Inputs'!$B$91="","",'Inputs'!$B$91&": a month") | C23: =IF('Inputs'!$B$91="","",'Needs calc'!$C$66) | D23: =IF('Inputs'!$B$91="","",'Needs calc'!$AK$66) | E23: =IF('Inputs'!$B$91="","",'Needs calc'!$BB$66) | F23: =IF('Inputs'!$B$91="","",'Needs calc'!$BS$66)
B24: =IF('Inputs'!$B$91="","",'Inputs'!$B$91) | C24: =IF('Inputs'!$B$91="","",IF(AND('Needs calc'!$C$4=1,'Inputs'!$Q$91=1),IF('Needs calc'!$C$90>=0,"Covered","Pot short R "&FIXED(ROUND(-'Needs calc'!$C$90,-3),0)),IF('Needs calc'!$C$65>0,"Short R "&FIXED(ROUND('Needs calc'!$C$65,-3),0),IF('Needs calc'!$C$65<0,"R "&FIXED(ROUND(-'Needs calc'!$C$65,-3),0)&" over","Covered")))) | D24: =IF('Inputs'!$B$91="","",IF(AND('Needs calc'!$AK$4=1,'Inputs'!$Q$91=1),IF('Needs calc'!$AK$90>=0,"Covered","Pot short R "&FIXED(ROUND(-'Needs calc'!$AK$90,-3),0)),IF('Needs calc'!$AK$65>0,"Short R "&FIXED(ROUND('Needs calc'!$AK$65,-3),0),IF('Needs calc'!$AK$65<0,"R "&FIXED(ROUND(-'Needs calc'!$AK$65,-3),0)&" over","Covered")))) | E24: =IF('Inputs'!$B$91="","",IF(AND('Needs calc'!$BB$4=1,'Inputs'!$Q$91=1),IF('Needs calc'!$BB$90>=0,"Covered","Pot short R "&FIXED(ROUND(-'Needs calc'!$BB$90,-3),0)),IF('Needs calc'!$BB$65>0,"Short R "&FIXED(ROUND('Needs calc'!$BB$65,-3),0),IF('Needs calc'!$BB$65<0,"R "&FIXED(ROUND(-'Needs calc'!$BB$65,-3),0)&" over","Covered")))) | F24: =IF('Inputs'!$B$91="","",IF(AND('Needs calc'!$BS$4=1,'Inputs'!$Q$91=1),IF('Needs calc'!$BS$90>=0,"Covered","Pot short R "&FIXED(ROUND(-'Needs calc'!$BS$90,-3),0)),IF('Needs calc'!$BS$65>0,"Short R "&FIXED(ROUND('Needs calc'!$BS$65,-3),0),IF('Needs calc'!$BS$65<0,"R "&FIXED(ROUND(-'Needs calc'!$BS$65,-3),0)&" over","Covered"))))
B25: =IF('Inputs'!$B$92="","",'Inputs'!$B$92&": capital set aside") | C25: =IF('Inputs'!$B$92="","",'Needs years'!$C$175+IF(AND('Needs calc'!$C$4=1,'Inputs'!$Q$92=1),'Needs calc'!$C$71,'Needs calc'!$C$67)) | D25: =IF('Inputs'!$B$92="","",'Needs years'!$C$175+IF(AND('Needs calc'!$AK$4=1,'Inputs'!$Q$92=1),'Needs calc'!$AK$71,'Needs calc'!$AK$67)) | E25: =IF('Inputs'!$B$92="","",'Needs years'!$C$175+IF(AND('Needs calc'!$BB$4=1,'Inputs'!$Q$92=1),'Needs calc'!$BB$71,'Needs calc'!$BB$67)) | F25: =IF('Inputs'!$B$92="","",'Needs years'!$C$175+IF(AND('Needs calc'!$BS$4=1,'Inputs'!$Q$92=1),'Needs calc'!$BS$71,'Needs calc'!$BS$67))
B26: =IF('Inputs'!$B$92="","",'Inputs'!$B$92&": a month") | C26: =IF('Inputs'!$B$92="","",'Needs calc'!$C$73) | D26: =IF('Inputs'!$B$92="","",'Needs calc'!$AK$73) | E26: =IF('Inputs'!$B$92="","",'Needs calc'!$BB$73) | F26: =IF('Inputs'!$B$92="","",'Needs calc'!$BS$73)
B27: =IF('Inputs'!$B$92="","",'Inputs'!$B$92) | C27: =IF('Inputs'!$B$92="","",IF(AND('Needs calc'!$C$4=1,'Inputs'!$Q$92=1),IF('Needs calc'!$C$90>=0,"Covered","Pot short R "&FIXED(ROUND(-'Needs calc'!$C$90,-3),0)),IF('Needs calc'!$C$72>0,"Short R "&FIXED(ROUND('Needs calc'!$C$72,-3),0),IF('Needs calc'!$C$72<0,"R "&FIXED(ROUND(-'Needs calc'!$C$72,-3),0)&" over","Covered")))) | D27: =IF('Inputs'!$B$92="","",IF(AND('Needs calc'!$AK$4=1,'Inputs'!$Q$92=1),IF('Needs calc'!$AK$90>=0,"Covered","Pot short R "&FIXED(ROUND(-'Needs calc'!$AK$90,-3),0)),IF('Needs calc'!$AK$72>0,"Short R "&FIXED(ROUND('Needs calc'!$AK$72,-3),0),IF('Needs calc'!$AK$72<0,"R "&FIXED(ROUND(-'Needs calc'!$AK$72,-3),0)&" over","Covered")))) | E27: =IF('Inputs'!$B$92="","",IF(AND('Needs calc'!$BB$4=1,'Inputs'!$Q$92=1),IF('Needs calc'!$BB$90>=0,"Covered","Pot short R "&FIXED(ROUND(-'Needs calc'!$BB$90,-3),0)),IF('Needs calc'!$BB$72>0,"Short R "&FIXED(ROUND('Needs calc'!$BB$72,-3),0),IF('Needs calc'!$BB$72<0,"R "&FIXED(ROUND(-'Needs calc'!$BB$72,-3),0)&" over","Covered")))) | F27: =IF('Inputs'!$B$92="","",IF(AND('Needs calc'!$BS$4=1,'Inputs'!$Q$92=1),IF('Needs calc'!$BS$90>=0,"Covered","Pot short R "&FIXED(ROUND(-'Needs calc'!$BS$90,-3),0)),IF('Needs calc'!$BS$72>0,"Short R "&FIXED(ROUND('Needs calc'!$BS$72,-3),0),IF('Needs calc'!$BS$72<0,"R "&FIXED(ROUND(-'Needs calc'!$BS$72,-3),0)&" over","Covered"))))
B28: Left in the family pot after every need | C28: =IF('Needs calc'!$C$4=1,'Needs calc'!$C$90,"") | D28: =IF('Needs calc'!$AK$4=1,'Needs calc'!$AK$90,"") | E28: =IF('Needs calc'!$BB$4=1,'Needs calc'!$BB$90,"") | F28: =IF('Needs calc'!$BS$4=1,'Needs calc'!$BS$90,"")
B29: Others receive, after their estate duty | C29: ='Needs calc'!$C$44-'Needs calc'!$C$45 | D29: ='Needs calc'!$AK$44-'Needs calc'!$AK$45 | E29: ='Needs calc'!$BB$44-'Needs calc'!$BB$45 | F29: ='Needs calc'!$BS$44-'Needs calc'!$BS$45
B30: Estate duty in total | C30: ='Needs calc'!$C$20 | D30: ='Needs calc'!$AK$20 | E30: ='Needs calc'!$BB$20 | F30: ='Needs calc'!$BS$20
B31: New life cover | C31: ='Needs calc'!$C$15 | D31: ='Needs calc'!$AK$15 | E31: ='Needs calc'!$BB$15 | F31: ='Needs calc'!$BS$15
B32: New premium | C32: =IF('Needs calc'!$C$15>0,"Yes","No") | D32: =IF('Needs calc'!$AK$15>0,"Yes","No") | E32: =IF('Needs calc'!$BB$15>0,"Yes","No") | F32: =IF('Needs calc'!$BS$15>0,"Yes","No")
B34: Things to know
B35: Moving a nomination uses what you already have: no new premium, but the person it is moved from receives less. One family pot lets the trustees pay each child what they need first and share what is left at the end.
B36: Policy money nominated to the trust or to a child carries its share of estate duty at the estate's average rate. New cover adds to the estate for duty, which is why it is more than the shortfall.
B37: Before a nomination is changed to the trust in your will, we confirm with the insurer that it accepts the trustees as the nominee.

Sheet Figures for quoting
B1: Duwalcoe Financial Consultants CC
B2: FSP 9978 | clinton@duwalcoe.co.za | 083 608 5617
B4: Winding up the estate: the figures
B5: Split the way quotes ask for them. Debts are shown separately.
C7: ="If "&'Inputs'!$C$9&" dies" | D7: =IF(AND(ISNUMBER('Inputs'!$C$100),'Inputs'!$C$100>0),"With the Legacy plan","")
B8: IN THE ESTATE: EXECUTOR'S FEES ARE CHARGED ON THESE
B9: Immovable property | C9: =SUMIFS('Inputs'!$D$22:$D$39,'Inputs'!$C$22:$C$39,"Property") | D9: =IF(AND(ISNUMBER('Inputs'!$C$100),'Inputs'!$C$100>0),SUMIFS('Inputs'!$D$22:$D$39,'Inputs'!$C$22:$C$39,"Property"),"")
B10: Movable property (vehicles, contents) | C10: =SUMIFS('Inputs'!$D$22:$D$39,'Inputs'!$C$22:$C$39,"Vehicle or contents") | D10: =IF(AND(ISNUMBER('Inputs'!$C$100),'Inputs'!$C$100>0),SUMIFS('Inputs'!$D$22:$D$39,'Inputs'!$C$22:$C$39,"Vehicle or contents"),"")
B11: Cash: bank accounts and deposits | C11: =SUMIFS('Inputs'!$D$22:$D$39,'Inputs'!$C$22:$C$39,"Cash and deposits") | D11: =IF(AND(ISNUMBER('Inputs'!$C$100),'Inputs'!$C$100>0),SUMIFS('Inputs'!$D$22:$D$39,'Inputs'!$C$22:$C$39,"Cash and deposits"),"")
B12: Listed shares and unit trusts | C12: =SUMIFS('Inputs'!$D$22:$D$39,'Inputs'!$C$22:$C$39,"Shares and unit trusts") | D12: =IF(AND(ISNUMBER('Inputs'!$C$100),'Inputs'!$C$100>0),SUMIFS('Inputs'!$D$22:$D$39,'Inputs'!$C$22:$C$39,"Shares and unit trusts"),"")
B13: Other investments (tax-free, loan accounts, business interests) | C13: =SUMIFS('Inputs'!$D$22:$D$39,'Inputs'!$C$22:$C$39,"Other investment")+SUMIFS('Inputs'!$D$22:$D$39,'Inputs'!$C$22:$C$39,"Tax-free investment")+SUMIFS('Inputs'!$D$22:$D$39,'Inputs'!$C$22:$C$39,"Loan account")+SUMIFS('Inputs'!$D$22:$D$39,'Inputs'!$C$22:$C$39,"Business interest") | D13: =IF(AND(ISNUMBER('Inputs'!$C$100),'Inputs'!$C$100>0),SUMIFS('Inputs'!$D$22:$D$39,'Inputs'!$C$22:$C$39,"Other investment")+SUMIFS('Inputs'!$D$22:$D$39,'Inputs'!$C$22:$C$39,"Tax-free investment")+SUMIFS('Inputs'!$D$22:$D$39,'Inputs'!$C$22:$C$39,"Loan account")+SUMIFS('Inputs'!$D$22:$D$39,'Inputs'!$C$22:$C$39,"Business interest"),"")
B14: Life assurance paid into the estate | C14: ='Workings'!$C$20 | D14: =IF(AND(ISNUMBER('Inputs'!$C$100),'Inputs'!$C$100>0),'Workings'!$C$20,"")
B15: Total in the estate | C15: =SUM(C9:C14) | D15: =IF(AND(ISNUMBER('Inputs'!$C$100),'Inputs'!$C$100>0),SUM(C9:C14),"")
B16: OUTSIDE THE ESTATE: NO EXECUTOR'S FEES
B17: Policies paid to a named person or spouse (counted for estate duty) | C17: ='Workings'!$C$22 | D17: =IF(AND(ISNUMBER('Inputs'!$C$100),'Inputs'!$C$100>0),'Workings'!$C$22,"")
B18: Approved group life (not counted) | C18: =SUMIFS('Inputs'!$D$59:$D$70,'Inputs'!$E$59:$E$70,"No") | D18: =IF(AND(ISNUMBER('Inputs'!$C$100),'Inputs'!$C$100>0),SUMIFS('Inputs'!$D$59:$D$70,'Inputs'!$E$59:$E$70,"No"),"")
B19: Retirement funds (not counted) | C19: =SUM('Inputs'!$D$76:$D$83) | D19: =IF(AND(ISNUMBER('Inputs'!$C$100),'Inputs'!$C$100>0),SUM('Inputs'!$D$76:$D$83),"")
B20: TOTALS
B21: Everything owned | C21: =C15+SUM(C17:C19) | D21: =IF(AND(ISNUMBER('Inputs'!$C$100),'Inputs'!$C$100>0),C15+SUM(C17:C19),"")
B22: Counted for estate duty | C22: ='Workings'!$C$23 | D22: =IF(AND(ISNUMBER('Inputs'!$C$100),'Inputs'!$C$100>0),'Workings'!$C$23,"")
B23: Liabilities | C23: ='Workings'!$C$59 | D23: =IF(AND(ISNUMBER('Inputs'!$C$100),'Inputs'!$C$100>0),'Workings'!$C$59,"")
B24: COST OF WINDING UP
B25: Executor's fees | C25: ='Workings'!$C$51 | D25: =IF(AND(ISNUMBER('Inputs'!$C$100),'Inputs'!$C$100>0),'Workings'!$D$51,"")
B26: Master's fees, funeral, notices and sundries | C26: ='Workings'!$C$50 | D26: =IF(AND(ISNUMBER('Inputs'!$C$100),'Inputs'!$C$100>0),'Workings'!$D$50,"")
B27: Property transfer and conveyancing | C27: ='Workings'!$C$52 | D27: =IF(AND(ISNUMBER('Inputs'!$C$100),'Inputs'!$C$100>0),'Workings'!$D$52,"")
B28: Agent's commission on property sold | C28: ='Workings'!$C$53 | D28: =IF(AND(ISNUMBER('Inputs'!$C$100),'Inputs'!$C$100>0),'Workings'!$D$53,"")
B29: Capital gains tax | C29: ='Workings'!$C$54 | D29: =IF(AND(ISNUMBER('Inputs'!$C$100),'Inputs'!$C$100>0),'Workings'!$D$54,"")
B30: Estate duty borne by the estate | C30: ='Workings'!$C$55 | D30: =IF(AND(ISNUMBER('Inputs'!$C$100),'Inputs'!$C$100>0),'Workings'!$D$55,"")
B31: Cost of winding up, before debts | C31: ='Workings'!$C$56 | D31: =IF(AND(ISNUMBER('Inputs'!$C$100),'Inputs'!$C$100>0),'Workings'!$D$56,"")
B32: Paid by the Legacy plan | C32: =-'Workings'!$C$57 | D32: =IF(AND(ISNUMBER('Inputs'!$C$100),'Inputs'!$C$100>0),-'Workings'!$D$57,"")
B33: Debts (not included above) | C33: ='Workings'!$C$59 | D33: =IF(AND(ISNUMBER('Inputs'!$C$100),'Inputs'!$C$100>0),'Workings'!$D$59,"")
B35: Cover paid into an estate is itself charged executor's fees; cover paid to a named person or trust is not.

Sheet Workings
B1: Duwalcoe Financial Consultants CC
B2: FSP 9978 | clinton@duwalcoe.co.za | 083 608 5617
B4: Workings
B5: Adviser reference and compliance record. Precise figures.
B7: 1. Capital gains tax on death | C7: Today | D7: With the plan
B8: ="Taxable income for the year"&IF('Inputs'!$C$17<>"",": "&'Inputs'!$C$17,"") | C8: =N('Inputs'!$C$16) | D8: =N('Inputs'!$C$16)
B9: Gains: value less base cost, on property, shares, unit trusts and other investments | C9: =SUM('Inputs'!$M$22:$M$39) | D9: =SUM('Inputs'!$M$22:$M$39)
B10: Less the primary residence exclusion | C10: =-SUM('Inputs'!$N$22:$N$39) | D10: =-SUM('Inputs'!$N$22:$N$39)
B11: Less the exclusion in the year of death | C11: =-MIN('Inputs'!$C$119,MAX(0,C9+C10)) | D11: =-MIN('Inputs'!$C$119,MAX(0,D9+D10))
B12: Net gain | C12: =MAX(0,C9+C10+C11) | D12: =MAX(0,D9+D10+D11)
B13: ="Added to taxable income: "&FIXED('Inputs'!$C$120,0)&"% of the net gain (the inclusion rate, not a tax rate)" | C13: =C12*'Inputs'!$C$120/100 | D13: =D12*'Inputs'!$C$120/100
B14: Tax on taxable income plus the gain added | C14: =(INDEX('Inputs'!$D$125:$D$131,MATCH(C8+C13,'Inputs'!$C$125:$C$131,1))+INDEX('Inputs'!$E$125:$E$131,MATCH(C8+C13,'Inputs'!$C$125:$C$131,1))/100*((C8+C13)-INDEX('Inputs'!$C$125:$C$131,MATCH(C8+C13,'Inputs'!$C$125:$C$131,1)))) | D14: =(INDEX('Inputs'!$D$125:$D$131,MATCH(D8+D13,'Inputs'!$C$125:$C$131,1))+INDEX('Inputs'!$E$125:$E$131,MATCH(D8+D13,'Inputs'!$C$125:$C$131,1))/100*((D8+D13)-INDEX('Inputs'!$C$125:$C$131,MATCH(D8+D13,'Inputs'!$C$125:$C$131,1))))
B15: Less tax on taxable income alone | C15: =-(INDEX('Inputs'!$D$125:$D$131,MATCH(C8,'Inputs'!$C$125:$C$131,1))+INDEX('Inputs'!$E$125:$E$131,MATCH(C8,'Inputs'!$C$125:$C$131,1))/100*((C8)-INDEX('Inputs'!$C$125:$C$131,MATCH(C8,'Inputs'!$C$125:$C$131,1)))) | D15: =-(INDEX('Inputs'!$D$125:$D$131,MATCH(D8,'Inputs'!$C$125:$C$131,1))+INDEX('Inputs'!$E$125:$E$131,MATCH(D8,'Inputs'!$C$125:$C$131,1))/100*((D8)-INDEX('Inputs'!$C$125:$C$131,MATCH(D8,'Inputs'!$C$125:$C$131,1))))
B16: Capital gains tax on death | C16: =IF(C12>0,ROUND(C14+C15,2),0) | D16: =IF(D12>0,ROUND(D14+D15,2),0)
B18: 2. Estate duty | C18: Today | D18: With the plan
B19: Assets in the estate | C19: =ROUND(SUM('Inputs'!$D$22:$D$39),2) | D19: =ROUND(SUM('Inputs'!$D$22:$D$39),2)
B20: Life cover paid into the estate | C20: =SUMIFS('Inputs'!$D$59:$D$70,'Inputs'!$C$59:$C$70,"Estate") | D20: =SUMIFS('Inputs'!$D$59:$D$70,'Inputs'!$C$59:$C$70,"Estate")
B21: Gross estate (handled by the executor) | C21: =C19+C20 | D21: =D19+D20
B22: Policies paid to a named person or spouse, counted for estate duty | C22: =SUMIFS('Inputs'!$D$59:$D$70,'Inputs'!$C$59:$C$70,"<>Estate",'Inputs'!$E$59:$E$70,"<>No") | D22: =SUMIFS('Inputs'!$D$59:$D$70,'Inputs'!$C$59:$C$70,"<>Estate",'Inputs'!$E$59:$E$70,"<>No")
B23: Gross dutiable estate | C23: =C21+C22 | D23: =D21+D22
B24: Less debts | C24: =-SUM('Inputs'!$D$45:$D$54) | D24: =-SUM('Inputs'!$D$45:$D$54)
B25: Less funeral | C25: =-'Inputs'!$C$111 | D25: =-'Inputs'!$C$111
