Workbook
Name FF_C_Title: 'Client and family'!$C$9
Name FF_C_Name: 'Client and family'!$C$10
Name FF_S_SpouseName: 'Client and family'!$D$10
Name FF_C_CallingName: 'Client and family'!$C$11
Name FF_C_IDNumber: 'Client and family'!$C$12
Name FF_S_SpouseIDNumber: 'Client and family'!$D$12
Name FF_C_DOB: 'Client and family'!$C$14
Name FF_S_SpouseDOB: 'Client and family'!$D$14
Name FF_C_Gender: 'Client and family'!$C$15
Name FF_C_Smoker: 'Client and family'!$C$16
Name FF_C_Cell: 'Client and family'!$C$17
Name FF_S_SpouseCell: 'Client and family'!$D$17
Name FF_C_Email: 'Client and family'!$C$18
Name FF_S_SpouseEmail: 'Client and family'!$D$18
Name FF_C_TelHome: 'Client and family'!$C$19
Name FF_C_TelWork: 'Client and family'!$C$20
Name FF_C_Address: 'Client and family'!$C$21
Name FF_C_POBox: 'Client and family'!$C$22
Name FF_C_Occupation: 'Client and family'!$C$23
Name FF_S_SpouseOccupation: 'Client and family'!$D$23
Name FF_C_Employer: 'Client and family'!$C$24
Name FF_C_Income: 'Client and family'!$C$25
Name FF_S_SpouseIncome: 'Client and family'!$D$25
Name FF_S_SpouseWorks: 'Client and family'!$D$26
Name FF_C_TaxNo: 'Client and family'!$C$27
Name FF_C_Education: 'Client and family'!$C$28
Name FF_C_Qualification: 'Client and family'!$C$29
Name FF_C_MaritalStatus: 'Client and family'!$C$30
Name FF_C_Anniversary: 'Client and family'!$C$31
Name FF_C_IsLead: 'Client and family'!$C$32
Name FF_K_kids: 'Client and family'!$B$36:$Z$36
Name FF_T_kids: 'Client and family'!$B$38:$Z$45
Name FF_W_dep_notes: 'Client and family'!$C$49
Name FF_M_ClientID: Lists!$Z$1
Name FF_M_ClientName: Lists!$Z$2
Name FF_M_Version: Lists!$Z$3
Name FF_M_ExportedAt: Lists!$Z$4
Name FF_M_ExportedBy: Lists!$Z$5
Name FF_M_TemplateVersion: Lists!$Z$7
Name FF_G_ValDate: 'Start here'!$C$19
Name FF_G_CompletedBy: 'Start here'!$C$20
Name FF_G_DateCompleted: 'Start here'!$C$21
Name FF_K_income: 'Income and expenses'!$B$8:$Z$8
Name FF_T_income: 'Income and expenses'!$B$11:$Z$20
Name FF_K_expense: 'Income and expenses'!$B$25:$Z$25
Name FF_T_expense: 'Income and expenses'!$B$28:$Z$42
Name FF_K_property: 'Assets and debts'!$B$9:$Z$9
Name FF_T_property: 'Assets and debts'!$B$12:$Z$19
Name FF_K_vehicle: 'Assets and debts'!$B$23:$Z$23
Name FF_T_vehicle: 'Assets and debts'!$B$26:$Z$31
Name FF_K_other: 'Assets and debts'!$B$35:$Z$35
Name FF_T_other: 'Assets and debts'!$B$38:$Z$52
Name FF_K_liability: 'Assets and debts'!$B$56:$Z$56
Name FF_T_liability: 'Assets and debts'!$B$59:$Z$70
Name FF_B1__id: 'Companies and trusts'!$Z$7
Name FF_B1_desc: 'Companies and trusts'!$C$8
Name FF_B1_entityType: 'Companies and trusts'!$C$9
Name FF_B1_mainUse: 'Companies and trusts'!$C$10
Name FF_B1_buySell: 'Companies and trusts'!$C$11
Name FF_B1_valBasis: 'Companies and trusts'!$C$12

Sheet Start here
B1: Duwalcoe Financial Consultants CC
B2: FSP 9978 | clinton@duwalcoe.co.za | 083 608 5617
B4: ="Fact find for "&IF('Client and family'!$C$10="","a new client",'Client and family'!$C$10)&IF('Client and family'!$D$10="",""," and "&'Client and family'!$D$10)
B6: How to fill it in
B7: 1. Type only in the yellow cells. Grey cells fill themselves in from what you type elsewhere, so each fact is typed once.
B8: 2. Start on the Client and family sheet. The names you type there appear in the drop-down lists on every other sheet.
B9: 3. All amounts are in rand, as at the date below. Rough figures are fine. Where you have guessed, choose Estimate in the Source column.
B10: 4. Leave out policies and investments arranged through Duwalcoe. They are already on our records.
B11: 5. Leave anything you are not sure of blank and we will go through it together.
B12: 6. The Summary sheet adds everything up as you go. Please email the completed workbook to clinton@duwalcoe.co.za.
B14: The colours
B15: Type here
B16: Filled in for you, nothing to type
B18: About this fact find
B19: Values as at (date)
... B21: Date completed

Sheet Client and family
B1: Duwalcoe Financial Consultants CC
B2: FSP 9978 | clinton@duwalcoe.co.za | 083 608 5617
B4: Client and family
B5: This sheet is the home of every name in the workbook. The names typed here appear in the drop-downs on the other sheets.
B7: 1. You and your spouse
B8: Detail | C8: =IF(C10="","You",C10) | D8: =IF(D10="","Your spouse or partner",D10)
B9: Title
B10: Full names
B11: Calling name (what we call you)
B12: SA ID number
B13: Date of birth (worked out from the ID, or as typed below) | C13: =IF(LEN(C12)=13,IFERROR(DATE(IF(VALUE(LEFT(C12,2))>MOD(YEAR(TODAY()),100),1900,2000)+VALUE(LEFT(C12,2)),VALUE(MID(C12,3,2)),VALUE(MID(C12,5,2))),""),IF(C14="","",C14)) | D13: =IF(LEN(D12)=13,IFERROR(DATE(IF(VALUE(LEFT(D12,2))>MOD(YEAR(TODAY()),100),1900,2000)+VALUE(LEFT(D12,2)),VALUE(MID(D12,3,2)),VALUE(MID(D12,5,2))),""),IF(D14="","",D14))
B14: Date of birth (only if no SA ID number)
B15: Gender (only if no SA ID number)
B16: Smoker
B17: Cell
B18: Email
B19: Home telephone
B20: Work telephone
B21: Physical address
B22: Postal address
B23: Occupation
B24: Employer
B25: Gross income a month (R)
... B35: Your children first, then anyone else in the family. Your spouse goes above, not here.
B36: Name | C36: IDNumber | D36: DOB | E36: Type | F36: Dependent | Z36: _id
B37: Full names | C37: SA ID number | D37: Date of birth (if no SA ID) | E37: Relationship to you | F37: Financially dependent on you? | G37: Age
G38: =IF(AND(LEN(C38)<>13,D38=""),"",DATEDIF(IF(LEN(C38)=13,IFERROR(DATE(IF(VALUE(LEFT(C38,2))>MOD(YEAR(TODAY()),100),1900,2000)+VALUE(LEFT(C38,2)),VALUE(MID(C38,3,2)),VALUE(MID(C38,5,2))),D38),D38),TODAY(),"Y"))
G39: =IF(AND(LEN(C39)<>13,D39=""),"",DATEDIF(IF(LEN(C39)=13,IFERROR(DATE(IF(VALUE(LEFT(C39,2))>MOD(YEAR(TODAY()),100),1900,2000)+VALUE(LEFT(C39,2)),VALUE(MID(C39,3,2)),VALUE(MID(C39,5,2))),D39),D39),TODAY(),"Y"))
G40: =IF(AND(LEN(C40)<>13,D40=""),"",DATEDIF(IF(LEN(C40)=13,IFERROR(DATE(IF(VALUE(LEFT(C40,2))>MOD(YEAR(TODAY()),100),1900,2000)+VALUE(LEFT(C40,2)),VALUE(MID(C40,3,2)),VALUE(MID(C40,5,2))),D40),D40),TODAY(),"Y"))
G41: =IF(AND(LEN(C41)<>13,D41=""),"",DATEDIF(IF(LEN(C41)=13,IFERROR(DATE(IF(VALUE(LEFT(C41,2))>MOD(YEAR(TODAY()),100),1900,2000)+VALUE(LEFT(C41,2)),VALUE(MID(C41,3,2)),VALUE(MID(C41,5,2))),D41),D41),TODAY(),"Y"))
G42: =IF(AND(LEN(C42)<>13,D42=""),"",DATEDIF(IF(LEN(C42)=13,IFERROR(DATE(IF(VALUE(LEFT(C42,2))>MOD(YEAR(TODAY()),100),1900,2000)+VALUE(LEFT(C42,2)),VALUE(MID(C42,3,2)),VALUE(MID(C42,5,2))),D42),D42),TODAY(),"Y"))
G43: =IF(AND(LEN(C43)<>13,D43=""),"",DATEDIF(IF(LEN(C43)=13,IFERROR(DATE(IF(VALUE(LEFT(C43,2))>MOD(YEAR(TODAY()),100),1900,2000)+VALUE(LEFT(C43,2)),VALUE(MID(C43,3,2)),VALUE(MID(C43,5,2))),D43),D43),TODAY(),"Y"))
G44: =IF(AND(LEN(C44)<>13,D44=""),"",DATEDIF(IF(LEN(C44)=13,IFERROR(DATE(IF(VALUE(LEFT(C44,2))>MOD(YEAR(TODAY()),100),1900,2000)+VALUE(LEFT(C44,2)),VALUE(MID(C44,3,2)),VALUE(MID(C44,5,2))),D44),D44),TODAY(),"Y"))
G45: =IF(AND(LEN(C45)<>13,D45=""),"",DATEDIF(IF(LEN(C45)=13,IFERROR(DATE(IF(VALUE(LEFT(C45,2))>MOD(YEAR(TODAY()),100),1900,2000)+VALUE(LEFT(C45,2)),VALUE(MID(C45,3,2)),VALUE(MID(C45,5,2))),D45),D45),TODAY(),"Y"))
B47: 3. Other dependants
B48: Anyone else you support or want provided for, for example an elderly parent or a disabled sibling.
B49: Other dependants to provide for

Sheet Income and expenses
B1: Duwalcoe Financial Consultants CC
B2: FSP 9978 | clinton@duwalcoe.co.za | 083 608 5617
B4: Income and expenses
B6: 1. Income
B7: Every regular income, before tax. One row per source.
B8: desc | C8: owner | D8: incomeType | E8: amountPM | F8: bonus | G8: taxable | H8: notes | Z8: _id
B9: Description (e.g. Salary, ABC Ltd) | C9: Whose income | D9: Type | E9: Gross amount a month (R) | F9: Annual bonus (R) | G9: Taxable? | H9: Notes
B10: Example: Salary, ABC Ltd | C10: ='Lists'!$A$2 | D10: Salary | E10: 45000 | F10: 45000 | G10: Yes | H10: 13th cheque in December
B21: Total income a month | E21: =SUM(E11:E20)
B23: 2. Monthly expenses
B24: What the household spends each month.
B25: desc | C25: expCategory | D25: amountPM | E25: notes | Z25: _id
B26: Description | C26: Category | D26: Amount a month (R) | E26: Notes
B27: Example: Household groceries and utilities | C27: Living expenses | D27: 18000
B43: Total expenses a month | D43: =SUM(D28:D42)
B45: 3. Cash flow
B46: Income a month | C46: =E21
B47: Expenses a month | C47: =D43
B48: Left over a month (shortfall in brackets) | C48: =E21-D43

Sheet Assets and debts
B1: Duwalcoe Financial Consultants CC
B2: FSP 9978 | clinton@duwalcoe.co.za | 083 608 5617
B4: Assets and debts in your own names
B5: Owner: choose your name, your spouse's name or Joint. Anything owned by a company or trust goes on the Companies and trusts sheet instead.
B7: 1. Property in your own names
B8: Market value is what it would sell for today. Base cost is what it cost plus improvements, for capital gains tax. Property owned by a company or trust goes on the Companies and trusts sheet, not here.
B9: desc | C9: owner | D9: value | E9: valueDate | F9: baseCost | G9: dateAcquired | H9: bondOut | I9: bondPM | J9: rentalPM | K9: primaryRes | L9: passesTo | M9: passesToName | N9: soldDeath | O9: soldDisab | P9: source | Q9: notes | Z9: _id
B10: Address and type of property | C10: Owner | D10: Market value today (R) | E10: Value as at | F10: Base cost incl. improvements (R) | G10: Date bought | H10: Bond owing (R) | I10: Bond a month (R) | J10: Rent received a month (R) | K10: Main home? | L10: Passes to at death | M10: Named person | N10: Sell at death? | O10: Sell if disabled? | P10: Source | Q10: Notes
B11: Example: 12 Beach Road, Hermanus | C11: Joint | D11: 3500000 | E11: 46295 | F11: 1800000 | G11: 41030 | H11: 1200000 | I11: 14500 | K11: Yes | L11: Spouse | N11: No | O11: No | P11: Estimate | Q11: ABSA bond
B21: 2. Vehicles
B22: Cars, bakkies, boats, caravans and trailers.
B23: desc | C23: owner | D23: value | E23: financeOut | F23: financePM | G23: passesTo | H23: passesToName | I23: soldDeath | J23: source | K23: notes | Z23: _id
B24: Make, model and year | C24: Owner | D24: Value today (R) | E24: Finance owing (R) | F24: Finance a month (R) | G24: Passes to at death | H24: Named person | I24: Sell at death? | J24: Source | K24: Notes
B25: Example: 2021 Toyota Hilux 2.8 | C25: ='Lists'!$A$2 | D25: 520000 | E25: 180000 | F25: 9800 | G25: Spouse | I25: No | J25: Estimate
B33: 3. Bank accounts, investments and other assets
B34: Bank and savings accounts, shares and unit trusts held directly, money lent to family, household contents, jewellery, art, firearms, collections. Policies and investments arranged through Duwalcoe are already on our records.
B35: desc | C35: owner | D35: type | E35: value | F35: baseCost | G35: dateAcquired | H35: passesTo | I35: passesToName | J35: source | K35: notes | Z35: _id
B36: Description | C36: Owner | D36: Type | E36: Value today (R) | F36: Base cost (R) | G36: Date acquired | H36: Passes to at death | I36: Named person | J36: Source | K36: Notes
B37: Example: FNB savings account | C37: ='Lists'!$A$2 | D37: Cash / Savings | E37: 85000 | H37: Estate | J37: Statement
B54: 4. Debts
B55: Credit cards, overdrafts, personal loans, store accounts, loans from family, tax owed to SARS. Bonds and vehicle finance are entered above.
B56: desc | C56: owner | D56: liabType | E56: balance | F56: interestRate | G56: paymentPM | H56: payOffDisab | I56: source | J56: notes | Z56: _id
B57: Lender and type of debt | C57: Whose debt | D57: Type | E57: Balance owing (R) | F57: Interest rate (% a year) | G57: Payment a month (R) | H57: Pay off if disabled? | I57: Source | J57: Notes
B58: Example: ABSA credit card | C58: ='Lists'!$A$2 | D58: Credit Card | E58: 25000 | F58: 19.5 | G58: 1500 | H58: Yes | I58: Statement

Sheet Companies and trusts
B1: Duwalcoe Financial Consultants CC
B2: FSP 9978 | clinton@duwalcoe.co.za | 083 608 5617
B4: Companies, close corporations and trusts
B5: One block for each company, CC or trust that you or your spouse hold an interest in. Property inside a company or trust is entered here, never as your own property. The value of each share is worked out from what the entity holds, unless you type your accountant's value.
B7: Company, CC or trust 1
B8: Name of the company, CC or trust
B9: Type
B10: Main use of the business
B11: Buy and sell agreement in place?
B12: Valuation basis
B13: Figures as at
B14: Source of the figures
... B19: Notes
B20: Each of you | C20: ='Lists'!$A$2 | D20: ='Lists'!$A$3
B21: % held (type 60 for 60%)
B22: Loan account: Credit = the entity owes you, Debit = you owe it
B23: Loan account balance (R)
B24: What your shares cost (R)
B25: Date you acquired the shares
B26: Actively involved in running it?
B27: Accountant's value of your share (R), only if you have one
B29: What the company or trust holds
B30: Property at market value with its base cost, bonds, cash, other assets and other debts. Not the loan accounts above: they are counted automatically.
B31: desc | C31: kind | D31: value | E31: baseCost | F31: source | G31: notes | Z31: _id
B32: What it holds | C32: Kind | D32: Market value or balance (R) | E32: Base cost (R) (property) | F32: Source | G32: Notes
B33: Example: Erf 12, Onrus (let to tenants) | C33: Property | D33: 5000000 | E33: 2000000 | F33: Valuation
B44: Assets of the entity (including loans owed to it by you) | C44: =SUMIFS(D34:D43,C34:C43,"Property")+SUMIFS(D34:D43,C34:C43,"Other asset")+IF(C22="Debit",N(C23),0)+IF(D22="Debit",N(D23),0)
B45: Debts of the entity (including loan accounts it owes you) | C45: =SUMIFS(D34:D43,C34:C43,"Bond")+SUMIFS(D34:D43,C34:C43,"Other debt")+IF(C22="Credit",N(C23),0)+IF(D22="Credit",N(D23),0)
B46: Net assets | C46: =C44-C45
B47: Value of each share | C47: ='Lists'!$A$2 | D47: ='Lists'!$A$3
B48: Worked out: net assets x % held (a company share is never below nil) | C48: =IF(OR(C9="Trust",C21=""),"",ROUND(IF(OR(C9="Partnership",C9="Sole Proprietor"),C46,MAX(0,C46))*N(C21)/100,0)) | D48: =IF(OR(C9="Trust",D21=""),"",ROUND(IF(OR(C9="Partnership",C9="Sole Proprietor"),C46,MAX(0,C46))*N(D21)/100,0))
B49: Value used (the accountant's value if given, otherwise worked out) | C49: =IF(C9="Trust","",IF(C27<>"",C27,C48)) | D49: =IF(C9="Trust","",IF(D27<>"",D27,D48))
B50: A trust has no shares: only the loan accounts belong to your estates.
B53: Company, CC or trust 2
B54: Name of the company, CC or trust
B55: Type
B56: Main use of the business
B57: Buy and sell agreement in place?
B58: Valuation basis
B59: Figures as at
...

Sheet Needs
B1: Duwalcoe Financial Consultants CC
B2: FSP 9978 | clinton@duwalcoe.co.za | 083 608 5617
B4: Needs
B6: What you want provided for
B7: For each need: what happens (death, disability, dread disease, retirement), whether it is a monthly income or a once-off amount, and for whom (death only).
B8: desc | C8: scenario | D8: needType | E8: amount | F8: years | G8: esc | H8: benTo | I8: benName | J8: notes | Z8: _id
B9: Description (e.g. Income for the family, Education) | C9: If this happens | D9: Monthly income or once-off? | E9: Amount (R): a month, or the once-off total | F9: For how many years (income) | G9: Increase % a year (blank = inflation) | H9: For whom (death only) | I9: Named person | J9: Notes
B10: Example: Income for the family | C10: Death | D10: Monthly income | E10: 40000 | F10: 20 | H10: Spouse

Sheet Will
B1: Duwalcoe Financial Consultants CC
B2: FSP 9978 | clinton@duwalcoe.co.za | 083 608 5617
B4: Will instructions
B5: Your wishes for the attorney who drafts your will. This is not a will. Names and family details come from the Client and family sheet.
B8: 1. You (the testator)
B9: Full names | C9: ='Client and family'!$C$10
B10: ID number | C10: ='Client and family'!$C$12
B11: Marital status and regime | C11: ='Client and family'!$C$30
B12: Place of birth
B13: If divorced or widowed: the date
B15: 2. Your spouse or life partner
B16: Spouse or partner: full names | C16: ='Client and family'!$D$10
B17: Date of marriage | C17: =IF('Client and family'!$C$31="","",'Client and family'!$C$31)
B18: Place of marriage
B19: Antenuptial contract and accrual: notes for the attorney
B21: 3. Children and dependants
B22: Child or family member (from the Client and family sheet) | C22: Notes for the attorney (special needs, anything to know)
B23: =IF('Client and family'!$B$38="","",'Client and family'!$B$38)
B24: =IF('Client and family'!$B$39="","",'Client and family'!$B$39)
B25: =IF('Client and family'!$B$40="","",'Client and family'!$B$40)
B26: =IF('Client and family'!$B$41="","",'Client and family'!$B$41)
B27: =IF('Client and family'!$B$42="","",'Client and family'!$B$42)
B28: =IF('Client and family'!$B$43="","",'Client and family'!$B$43)
B29: =IF('Client and family'!$B$44="","",'Client and family'!$B$44)
B30: =IF('Client and family'!$B$45="","",'Client and family'!$B$45)
B31: Other dependants to provide for | C31: =IF('Client and family'!$C$49="","",'Client and family'!$C$49)
B33: 4. Existing will
B34: Current position
B35: Date of existing will
B36: Drafted by
B37: Where the existing will or codicil is kept
B38: Revoke all prior wills and codicils when the new will is signed?
B40: 5. Guardian for minor children
B41: Not applicable (no minor children, or the other parent has full guardianship)?
B42: Primary guardian: full names
B43: Primary guardian: ID number
B44: Primary guardian: relationship
B45: Primary guardian: contact
... B65: 7. Specific bequests
B66: item | C66: ben | D66: pre
...

Sheet Summary
B1: Duwalcoe Financial Consultants CC
B2: FSP 9978 | clinton@duwalcoe.co.za | 083 608 5617
B4: Summary: what you own and what you owe
B5: This sheet adds up as the others are completed. Nothing to type here. Your cost of dying is worked out separately, in your financial needs analysis.
B6: Values as at | C6: =IF('Start here'!$C$19="","Not yet given",'Start here'!$C$19)
C8: ='Lists'!$A$2 | D8: ='Lists'!$A$3 | E8: Joint | F8: Total
B9: What you own
B10: Property in your own names | C10: =SUMIFS('Assets and debts'!$D$12:$D$19,'Assets and debts'!$C$12:$C$19,'Lists'!$A$2) | D10: =SUMIFS('Assets and debts'!$D$12:$D$19,'Assets and debts'!$C$12:$C$19,'Lists'!$A$3) | E10: =SUMIFS('Assets and debts'!$D$12:$D$19,'Assets and debts'!$C$12:$C$19,"Joint") | F10: =SUM(C10:E10)
B11: Your shares in companies and CCs | C11: =N('Companies and trusts'!$C$49)+N('Companies and trusts'!$C$94)+N('Companies and trusts'!$C$139)+N('Companies and trusts'!$C$184) | D11: =N('Companies and trusts'!$D$49)+N('Companies and trusts'!$D$94)+N('Companies and trusts'!$D$139)+N('Companies and trusts'!$D$184) | E11: 0 | F11: =SUM(C11:E11)
B12: Money owed to you (loan accounts and loans) | C12: =IF('Companies and trusts'!$C$22="Credit",N('Companies and trusts'!$C$23),0)+IF('Companies and trusts'!$C$68="Credit",N('Companies and trusts'!$C$69),0)+IF('Companies and trusts'!$C$113="Credit",N('Companies and trusts'!$C$114),0)+IF('Companies and trusts'!$C$158="Credit",N('Companies and trusts'!$C$159),0)+SUMIFS('Assets and debts'!$E$38:$E$52,'Assets and debts'!$C$38:$C$52,'Lists'!$A$2,'Assets and debts'!$D$38:$D$52,"Loan Account") | D12: =IF('Companies and trusts'!$D$22="Credit",N('Companies and trusts'!$D$23),0)+IF('Companies and trusts'!$D$68="Credit",N('Companies and trusts'!$D$69),0)+IF('Companies and trusts'!$D$113="Credit",N('Companies and trusts'!$D$114),0)+IF('Companies and trusts'!$D$158="Credit",N('Companies and trusts'!$D$159),0)+SUMIFS('Assets and debts'!$E$38:$E$52,'Assets and debts'!$C$38:$C$52,'Lists'!$A$3,'Assets and debts'!$D$38:$D$52,"Loan Account") | E12: =SUMIFS('Assets and debts'!$E$38:$E$52,'Assets and debts'!$C$38:$C$52,"Joint",'Assets and debts'!$D$38:$D$52,"Loan Account") | F12: =SUM(C12:E12)
B13: Bank accounts and investments | C13: =SUM(SUMIFS('Assets and debts'!$E$38:$E$52,'Assets and debts'!$C$38:$C$52,'Lists'!$A$2,'Assets and debts'!$D$38:$D$52,{"Cash / Savings","Fixed Deposit","Shares / Unit Trusts","Crypto"})) | D13: =SUM(SUMIFS('Assets and debts'!$E$38:$E$52,'Assets and debts'!$C$38:$C$52,'Lists'!$A$3,'Assets and debts'!$D$38:$D$52,{"Cash / Savings","Fixed Deposit","Shares / Unit Trusts","Crypto"})) | E13: =SUM(SUMIFS('Assets and debts'!$E$38:$E$52,'Assets and debts'!$C$38:$C$52,"Joint",'Assets and debts'!$D$38:$D$52,{"Cash / Savings","Fixed Deposit","Shares / Unit Trusts","Crypto"})) | F13: =SUM(C13:E13)
B14: Vehicles, contents and other assets | C14: =SUMIFS('Assets and debts'!$D$26:$D$31,'Assets and debts'!$C$26:$C$31,'Lists'!$A$2)+SUMIFS('Assets and debts'!$E$38:$E$52,'Assets and debts'!$C$38:$C$52,'Lists'!$A$2,'Assets and debts'!$D$38:$D$52,"<>Loan Account",'Assets and debts'!$D$38:$D$52,"<>Cash / Savings",'Assets and debts'!$D$38:$D$52,"<>Fixed Deposit",'Assets and debts'!$D$38:$D$52,"<>Shares / Unit Trusts",'Assets and debts'!$D$38:$D$52,"<>Crypto") | D14: =SUMIFS('Assets and debts'!$D$26:$D$31,'Assets and debts'!$C$26:$C$31,'Lists'!$A$3)+SUMIFS('Assets and debts'!$E$38:$E$52,'Assets and debts'!$C$38:$C$52,'Lists'!$A$3,'Assets and debts'!$D$38:$D$52,"<>Loan Account",'Assets and debts'!$D$38:$D$52,"<>Cash / Savings",'Assets and debts'!$D$38:$D$52,"<>Fixed Deposit",'Assets and debts'!$D$38:$D$52,"<>Shares / Unit Trusts",'Assets and debts'!$D$38:$D$52,"<>Crypto") | E14: =SUMIFS('Assets and debts'!$D$26:$D$31,'Assets and debts'!$C$26:$C$31,"Joint")+SUMIFS('Assets and debts'!$E$38:$E$52,'Assets and debts'!$C$38:$C$52,"Joint",'Assets and debts'!$D$38:$D$52,"<>Loan Account",'Assets and debts'!$D$38:$D$52,"<>Cash / Savings",'Assets and debts'!$D$38:$D$52,"<>Fixed Deposit",'Assets and debts'!$D$38:$D$52,"<>Shares / Unit Trusts",'Assets and debts'!$D$38:$D$52,"<>Crypto") | F14: =SUM(C14:E14)
B15: Total you own | C15: =C10+C11+C12+C13+C14 | D15: =D10+D11+D12+D13+D14 | E15: =E10+E11+E12+E13+E14 | F15: =SUM(C15:E15)
B17: What you owe
B18: Bonds on your property | C18: =SUMIFS('Assets and debts'!$H$12:$H$19,'Assets and debts'!$C$12:$C$19,'Lists'!$A$2) | D18: =SUMIFS('Assets and debts'!$H$12:$H$19,'Assets and debts'!$C$12:$C$19,'Lists'!$A$3) | E18: =SUMIFS('Assets and debts'!$H$12:$H$19,'Assets and debts'!$C$12:$C$19,"Joint") | F18: =SUM(C18:E18)
B19: Finance on vehicles | C19: =SUMIFS('Assets and debts'!$E$26:$E$31,'Assets and debts'!$C$26:$C$31,'Lists'!$A$2) | D19: =SUMIFS('Assets and debts'!$E$26:$E$31,'Assets and debts'!$C$26:$C$31,'Lists'!$A$3) | E19: =SUMIFS('Assets and debts'!$E$26:$E$31,'Assets and debts'!$C$26:$C$31,"Joint") | F19: =SUM(C19:E19)
B20: Other debts | C20: =SUMIFS('Assets and debts'!$E$59:$E$70,'Assets and debts'!$C$59:$C$70,'Lists'!$A$2) | D20: =SUMIFS('Assets and debts'!$E$59:$E$70,'Assets and debts'!$C$59:$C$70,'Lists'!$A$3) | E20: =SUMIFS('Assets and debts'!$E$59:$E$70,'Assets and debts'!$C$59:$C$70,"Joint") | F20: =SUM(C20:E20)
B21: Loan accounts you owe your companies and trusts | C21: =IF('Companies and trusts'!$C$22="Debit",N('Companies and trusts'!$C$23),0)+IF('Companies and trusts'!$C$68="Debit",N('Companies and trusts'!$C$69),0)+IF('Companies and trusts'!$C$113="Debit",N('Companies and trusts'!$C$114),0)+IF('Companies and trusts'!$C$158="Debit",N('Companies and trusts'!$C$159),0) | D21: =IF('Companies and trusts'!$D$22="Debit",N('Companies and trusts'!$D$23),0)+IF('Companies and trusts'!$D$68="Debit",N('Companies and trusts'!$D$69),0)+IF('Companies and trusts'!$D$113="Debit",N('Companies and trusts'!$D$114),0)+IF('Companies and trusts'!$D$158="Debit",N('Companies and trusts'!$D$159),0) | E21: 0 | F21: =SUM(C21:E21)
B22: Total you owe | C22: =C18+C19+C20+C21 | D22: =D18+D19+D20+D21 | E22: =E18+E19+E20+E21 | F22: =SUM(C22:E22)
B24: Net worth (what you own less what you owe) | C24: =C15-C22 | D24: =D15-D22 | E24: =E15-E22 | F24: =SUM(C24:E24)
B26: Inside your companies and trusts (shown separately, not added above)
B27: Property held by your companies and trusts | F27: =SUMIFS('Companies and trusts'!$D$34:$D$43,'Companies and trusts'!$C$34:$C$43,"Property")+SUMIFS('Companies and trusts'!$D$79:$D$88,'Companies and trusts'!$C$79:$C$88,"Property")+SUMIFS('Companies and trusts'!$D$124:$D$133,'Companies and trusts'!$C$124:$C$133,"Property")+SUMIFS('Companies and trusts'!$D$169:$D$178,'Companies and trusts'!$C$169:$C$178,"Property")
B28: Bonds and other debts of your companies and trusts | F28: =SUMIFS('Companies and trusts'!$D$34:$D$43,'Companies and trusts'!$C$34:$C$43,"Bond")+SUMIFS('Companies and trusts'!$D$79:$D$88,'Companies and trusts'!$C$79:$C$88,"Bond")+SUMIFS('Companies and trusts'!$D$124:$D$133,'Companies and trusts'!$C$124:$C$133,"Bond")+SUMIFS('Companies and trusts'!$D$169:$D$178,'Companies and trusts'!$C$169:$C$178,"Bond")+SUMIFS('Companies and trusts'!$D$34:$D$43,'Companies and trusts'!$C$34:$C$43,"Other debt")+SUMIFS('Companies and trusts'!$D$79:$D$88,'Companies and trusts'!$C$79:$C$88,"Other debt")+SUMIFS('Companies and trusts'!$D$124:$D$133,'Companies and trusts'!$C$124:$C$133,"Other debt")+SUMIFS('Companies and trusts'!$D$169:$D$178,'Companies and trusts'!$C$169:$C$178,"Other debt")
B30: How complete is it?
B31: Figures marked as estimates | F31: =COUNTIF('Assets and debts'!$P$12:$P$19,"Estimate")+COUNTIF('Assets and debts'!$J$26:$J$31,"Estimate")+COUNTIF('Assets and debts'!$J$38:$J$52,"Estimate")+COUNTIF('Assets and debts'!$I$59:$I$70,"Estimate")+COUNTIF('Companies and trusts'!$C$14,"Estimate")+COUNTIF('Companies and trusts'!$C$60,"Estimate")+COUNTIF('Companies and trusts'!$C$105,"Estimate")+COUNTIF('Companies and trusts'!$C$150,"Estimate")+COUNTIF('Companies and trusts'!$F$34:$F$43,"Estimate")+COUNTIF('Companies and trusts'!$F$79:$F$88,"Estimate")+COUNTIF('Companies and trusts'!$F$124:$F$133,"Estimate")+COUNTIF('Companies and trusts'!$F$169:$F$178,"Estimate")
B32: Property, shares and investments with no base cost given | F32: =SUMPRODUCT(('Assets and debts'!$D$12:$D$19>0)*('Assets and debts'!$F$12:$F$19=""))+SUMPRODUCT(('Assets and debts'!$E$38:$E$52>0)*('Assets and debts'!$D$38:$D$52="Shares / Unit Trusts")*('Assets and debts'!$F$38:$F$52=""))+SUMPRODUCT(('Assets and debts'!$E$38:$E$52>0)*('Assets and debts'!$D$38:$D$52="Business Interest")*('Assets and debts'!$F$38:$F$52=""))+SUMPRODUCT(('Assets and debts'!$E$38:$E$52>0)*('Assets and debts'!$D$38:$D$52="Crypto")*('Assets and debts'!$F$38:$F$52=""))+IF(AND(N('Companies and trusts'!$C$21)>0,'Companies and trusts'!$C$24=""),1,0)+IF(AND(N('Companies and trusts'!$D$21)>0,'Companies and trusts'!$D$24=""),1,0)+IF(AND(N('Companies and trusts'!$C$67)>0,'Companies and trusts'!$C$70=""),1,0)+IF(AND(N('Companies and trusts'!$D$67)>0,'Companies and trusts'!$D$70=""),1,0)+IF(AND(N('Companies and trusts'!$C$112)>0,'Companies and trusts'!$C$115=""),1,0)+IF(AND(N('Companies and trusts'!$D$112)>0,'Companies and trusts'!$D$115=""),1,0)+IF(AND(N('Companies and trusts'!$C$157)>0,'Companies and trusts'!$C$160=""),1,0)+IF(AND(N('Companies and trusts'!$D$157)>0,'Companies and trusts'!$D$160=""),1,0)+SUMPRODUCT(('Companies and trusts'!$D$34:$D$43>0)*('Companies and trusts'!$C$34:$C$43="Property")*('Companies and trusts'!$E$34:$E$43=""))+SUMPRODUCT(('Companies and trusts'!$D$79:$D$88>0)*('Companies and trusts'!$C$79:$C$88="Property")*('Companies and trusts'!$E$79:$E$88=""))+SUMPRODUCT(('Companies and trusts'!$D$124:$D$133>0)*('Companies and trusts'!$C$124:$C$133="Property")*('Companies and trusts'!$E$124:$E$133=""))+SUMPRODUCT(('Companies and trusts'!$D$169:$D$178>0)*('Companies and trusts'!$C$169:$C$178="Property")*('Companies and trusts'!$E$169:$E$178=""))
B34: =IF('Client and family'!$D$10="","You own R ","Together you own R ")&TEXT(F15,"#,##0")&" and owe R "&TEXT(F22,"#,##0")&", a net worth of R "&TEXT(F24,"#,##0")&"."&IF(F31>0," "&F31&IF(F31=1," figure is an estimate."," figures are estimates."),"")&IF(F32>0," "&F32&IF(F32=1," asset has"," assets have")&" no base cost yet, which we need for capital gains tax.","")

Sheet Lists
A1: owners | B1: family names | C1: asset names | D1: titles | E1: gender | F1: yesno | G1: lead | H1: marital | I1: edu | J1: famRel | K1: incType | L1: expCat | M1: liabType | N1: otherType | O1: entityType | P1: valBasis | Q1: mainUse | R1: loanAcc | S1: holdKind | T1: source | U1: passes | V1: scenario | W1: needType | X1: forWhom | Y1: ClientID | Z1: w_tr_choice | AA1: w_tr_term | AB1: w_res_choice | AC1: w_sa_off | AD1: w_sa_fire | AE1: w_lw | AF1: w_organ | AG1: w_fw | AH1: w_fw_cover | AI1: w_da_social | AJ1: w_lo | AK1: w_ex_security | AL1: w_ex_fee | AM1: w_cl_lang | AN1: w_cl_wt | AO1: w_cl_wt_sp_inc | AP1: w_cl_wt_kids_cap | AQ1: w_cl_exec | AR1: w_cl_collect
A2: =IF('Client and family'!$C$11<>"",'Client and family'!$C$11,IF('Client and family'!$C$10<>"",LEFT(TRIM('Client and family'!$C$10),FIND(" ",TRIM('Client and family'!$C$10)&" ")-1),"Client")) | B2: =IF('Client and family'!$D$10="","",'Client and family'!$D$10) | C2: =IF('Assets and debts'!$B$12="",""," "&'Assets and debts'!$B$12) | D2: Mr. | E2: Male | F2: Yes | G2: Client | H2: Single | I2: School - no matric | J2: Child | K2: Salary | L2: Living expenses | M2: Personal Loan | N2: Cash / Savings | O2: Pty Ltd | P2: Latest financials | Q2: Active trading business | R2: None | S2: Property | T2: Books | U2: Spouse | V2: Death | W2: Monthly income | X2: Spouse | Y2: ClientName | Z2: Yes — establish a testamentary trust | AA2: Terminates when beneficiary reaches a set age (below) | AB2: Entire residue to my spouse / life partner | AC2: None | AD2: None | AE2: Yes — I wish a living will to be drafted | AF2: I wish to donate my organs and tissues where medically suitable | AG2: Burial | AH2: I have a funeral policy (details below) | AI2: Memorialised | AJ2: Yes — a separate letter of wishes will be drafted | AK2: Waive security (bond of security) — usual for a family executor | AL2: Agreed reduced rate (below) | AM2: English | AN2: Yes | AO2: Yes | AP2: Yes | AQ2: Yes | AR2: Yes
A3: =IF('Client and family'!$D$10<>"",LEFT(TRIM('Client and family'!$D$10),FIND(" ",TRIM('Client and family'!$D$10)&" ")-1),"Spouse") | B3: =IF('Client and family'!$B$38="","",'Client and family'!$B$38) | C3: =IF('Assets and debts'!$B$13="",""," "&'Assets and debts'!$B$13) | D3: Mrs. | E3: Female | F3: No | G3: Lead | H3: Engaged | I3: Matric | J3: Parent | K3: Dividends | L3: Bond repayment | M3: Credit Card | N3: Fixed Deposit | O3: CC | P3: Informal estimate | Q3: Mainly property to let | R3: Credit | S3: Bond | T3: Statement | U3: Estate | V3: Disability | W3: Once-off capital | X3: Estate | Y3: Version | Z3: 1.1 | AA3: Trustees may pay capital sooner for education, medical, first home, etc. | AB3: Entire residue to my children equally, per stirpes | AC3: I hold assets offshore (a separate offshore will may be recommended) | AD3: I own firearms (beneficiary must hold a valid licence) | AE3: No — I do not want a living will | AF3: I do not wish to donate organs or tissues | AG3: Cremation | AH3: None | AI3: Closed | AJ3: No | AK3: Require security | AL3: Full statutory rate of 3.5% + VAT | AM3: Afrikaans | AN3: No | AO3: No | AP3: No | AQ3: No | AR3: No
A4: Joint | B4: =IF('Client and family'!$B$39="","",'Client and family'!$B$39) | C4: =IF('Assets and debts'!$B$14="",""," "&'Assets and debts'!$B$14) | D4: Ms. | H4: Married - ANC with accrual | I4: Diploma / Certificate | J4: Sibling | K4: Rental Income | L4: Vehicle finance | M4: Vehicle Finance | N4: Shares / Unit Trusts | O4: Trust | P4: Other | Q4: Mainly investments (shares, cash, loans) | R4: Debit | S4: Other asset | T4: Valuation | U4: Named person | V4: Dread Disease | X4: Named person | Y4: ExportedAt | Z4: Only if beneficiaries are still minors at date of death | AA4: Income distributed as needed; capital held until termination age | AB4: Entire residue to my children equally, per capita | AE4: I already have a living will (date below) | AF4: I am already a registered organ donor | AG4: No preference — leave to family | AI4: Transferred | AM4: Other (below)
B5: =IF('Client and family'!$B$40="","",'Client and family'!$B$40) | C5: =IF('Assets and debts'!$B$15="",""," "&'Assets and debts'!$B$15) | D5: Miss | H5: Married - ANC without accrual | I5: Degree | J5: Dependant | K5: Business Income | L5: School / university fees | M5: Home Bond | N5: Business Interest | O5: Partnership | Q5: Mixed (trading plus letting or investments) | S5: Other debt | T5: Estimate | V5: Retirement | Y5: ExportedBy | AB5: Split as follows (table below)
B6: =IF('Client and family'!$B$41="","",'Client and family'!$B$41) | C6: =IF('Assets and debts'!$B$16="",""," "&'Assets and debts'!$B$16) | D6: Dr. | H6: Married in COP | I6: Post Graduate | J6: Other | K6: State Pension (SASSA) | L6: Medical / medical aid | M6: Overdraft | N6: Loan Account | O6: Sole Proprietor | V6: Other
B7: =IF('Client and family'!$B$42="","",'Client and family'!$B$42) | C7: =IF('Assets and debts'!$B$17="",""," "&'Assets and debts'!$B$17) | D7: Prof. | H7: Life partner | I7: Other | K7: Annuity Income | L7: Insurance premiums | M7: Store Account | N7: Crypto | O7: Other | Y7: TemplateVersion | Z7: 1.1
B8: =IF('Client and family'!$B$43="","",'Client and family'!$B$43) | C8: =IF('Assets and debts'!$B$18="",""," "&'Assets and debts'!$B$18) | D8: Rev. | H8: Divorced | K8: Investment Income | L8: Entertainment | M8: Tax Debt | N8: Art / Collectibles | Y8: Breaks | Z8: [["Assets and debts",53],["Companies and trusts",51],["Companies and trusts",96],["Companies and trusts",141],["Will",63]]
B9: =IF('Client and family'!$B$44="","",'Client and family'!$B$44) | C9: =IF('Assets and debts'!$B$19="",""," "&'Assets and debts'!$B$19) | D9: Adv. | H9: Widowed | K9: Other | L9: Maintenance / alimony | M9: Student Loan | N9: Household Contents
B10: =IF('Client and family'!$B$45="","",'Client and family'!$B$45) | C10: =IF('Assets and debts'!$B$26="",""," "&'Assets and debts'!$B$26) | L10: Other | M10: Other | N10: Other
C11: =IF('Assets and debts'!$B$27="",""," "&'Assets and debts'!$B$27)
C12: =IF('Assets and debts'!$B$28="",""," "&'Assets and debts'!$B$28)
C13: =IF('Assets and debts'!$B$29="",""," "&'Assets and debts'!$B$29)
C14: =IF('Assets and debts'!$B$30="",""," "&'Assets and debts'!$B$30)
C15: =IF('Assets and debts'!$B$31="",""," "&'Assets and debts'!$B$31)
C16: =IF('Assets and debts'!$B$38="",""," "&'Assets and debts'!$B$38)
C17: =IF('Assets and debts'!$B$39="",""," "&'Assets and debts'!$B$39)
C18: =IF('Assets and debts'!$B$40="",""," "&'Assets and debts'!$B$40)
C19: =IF('Assets and debts'!$B$41="",""," "&'Assets and debts'!$B$41)
C20: =IF('Assets and debts'!$B$42="",""," "&'Assets and debts'!$B$42)
C21: =IF('Assets and debts'!$B$43="",""," "&'Assets and debts'!$B$43)
C22: =IF('Assets and debts'!$B$44="",""," "&'Assets and debts'!$B$44)
C23: =IF('Assets and debts'!$B$45="",""," "&'Assets and debts'!$B$45)
C24: =IF('Assets and debts'!$B$46="",""," "&'Assets and debts'!$B$46)
C25: =IF('Assets and debts'!$B$47="",""," "&'Assets and debts'!$B$47)
C26: =IF('Assets and debts'!$B$48="",""," "&'Assets and debts'!$B$48)
C27: =IF('Assets and debts'!$B$49="",""," "&'Assets and debts'!$B$49)
C28: =IF('Assets and debts'!$B$50="",""," "&'Assets and debts'!$B$50)
C29: =IF('Assets and debts'!$B$51="",""," "&'Assets and debts'!$B$51)
C30: =IF('Assets and debts'!$B$52="",""," "&'Assets and debts'!$B$52)
C31: =IF('Companies and trusts'!$C$8="",""," "&'Companies and trusts'!$C$8)
C32: =IF('Companies and trusts'!$C$54="",""," "&'Companies and trusts'!$C$54)
C33: =IF('Companies and trusts'!$C$99="",""," "&'Companies and trusts'!$C$99)
C34: =IF('Companies and trusts'!$C$144="",""," "&'Companies and trusts'!$C$144)
